Workbook
Name DATOS1: [1]!CODPARADA[[#All],[1: Procesos ]]
Name DATOS1: [1]!CODPARADA[[#All],[1: Procesos ]]

Sheet Calculo de Troquelado
A1: 2013 | B1: Venta Normal | C1: Semiautomaticas | D1: 12 VELAS DE NOCHE | E1: 2000 | F1: 0.0048 | G1: 0.0035 | H1: =(F1-G1)/F1 -> 0.27083333 | I1: PAI | J1: PAI BLANCO 650 x 200 | K1: CAJA Nº 3 | L1: BOLSAS DE 120 X 80 | M1: 35 | N1: 14 | O1: =IFERROR(60*60*7.5*M1/E1/N1,"") -> 33.75 | P1: =IFERROR(60*60*7.5*M1/E1/O1,"") -> 14 | Q1: =IFERROR(P1/8,"") -> 1.75 | R1: =IFERROR(IF(P1>2,Q1,""),"") -> 1.75 | T1: =IF(V1>10,V1*M1/E1,"") -> 18.243243 | U1: 25.9 | V1: =60*60*7.5/U1 -> 1042.471 | W1: 45553 | X1: Christian
B4: Ciclo por golpe | C4: Cantidad de ´plancha por vez | D4: ciclo por plancha | E4: Seg/hora | F4: Min/seg | G4: Horas efectivas disponibles | H4: Cavidades | I4: Un x cajas | J4: META | K4: OEE 80% ( En 6 horas)
B5: 52.3 | C5: 3 | D5: =B5/C5 -> 17.433333 | E5: 60 | F5: 60 | G5: 7.5 | H5: 35 | I5: 2000 | J5: =(E5*F5*G5*H5)/(D5*I5) -> 27.10325 | K5: =J5*0.8 -> 21.6826
B13: Ciclo por golpe | C13: Cantidad de ´plancha por vez | D13: ciclo por plancha | J13: Meta | K13: OEE 80% ( En 6 horas)
B14: =D14*C$14 -> 101.25 | C14: 3 | D14: =E14*F14*G14*H14/(I14*J14) -> 33.75 | E14: 60 | F14: 60 | G14: 7.5 | H14: =M$1 -> 35 | I14: =E$1 -> 2000 | J14: 14 | K14: =J14*0.8 -> 11.2
B15: =D15*C$14 -> 94.5 | D15: =E15*F15*G15*H15/(I15*J15) -> 31.5 | E15: 60 | F15: 60 | G15: 7.5 | H15: =M$1 -> 35 | I15: =E$1 -> 2000 | J15: 15 | K15: =J15*0.8 -> 12
B16: =D16*C$14 -> 88.59375 | D16: =E16*F16*G16*H16/(I16*J16) -> 29.53125 | E16: 60 | F16: 60 | G16: 7.5 | H16: =M$1 -> 35 | I16: =E$1 -> 2000 | J16: 16 | K16: =J16*0.8 -> 12.8
B17: =D17*C$14 -> 83.382353 | D17: =E17*F17*G17*H17/(I17*J17) -> 27.794118 | E17: 60 | F17: 60 | G17: 7.5 | H17: =M$1 -> 35 | I17: =E$1 -> 2000 | J17: 17 | K17: =J17*0.8 -> 13.6
B18: =D18*C$14 -> 78.75 | D18: =E18*F18*G18*H18/(I18*J18) -> 26.25 | E18: 60 | F18: 60 | G18: 7.5 | H18: =M$1 -> 35 | I18: =E$1 -> 2000 | J18: 18 | K18: =J18*0.8 -> 14.4
B19: =D19*C$14 -> 74.605263 | D19: =E19*F19*G19*H19/(I19*J19) -> 24.868421 | E19: 60 | F19: 60 | G19: 7.5 | H19: =M$1 -> 35 | I19: =E$1 -> 2000 | J19: 19 | K19: =J19*0.8 -> 15.2
B20: =D20*C$14 -> 74.605263 | D20: =E20*F20*G20*H20/(I20*J20) -> 24.868421 | E20: 60 | F20: 60 | G20: 7.5 | H20: =M$1 -> 35 | I20: =E$1 -> 2000 | J20: 19 | K20: =J20*0.8 -> 15.2
B21: =D21*C$14 -> 70.875 | D21: =E21*F21*G21*H21/(I21*J21) -> 23.625 | E21: 60 | F21: 60 | G21: 7.5 | H21: =M$1 -> 35 | I21: =E$1 -> 2000 | J21: 20 | K21: =J21*0.8 -> 16
B22: =D22*C$14 -> 67.5 | D22: =E22*F22*G22*H22/(I22*J22) -> 22.5 | E22: 60 | F22: 60 | G22: 7.5 | H22: =M$1 -> 35 | I22: =E$1 -> 2000 | J22: 21 | K22: =J22*0.8 -> 16.8
B23: =D23*C$14 -> 64.431818 | D23: =E23*F23*G23*H23/(I23*J23) -> 21.477273 | E23: 60 | F23: 60 | G23: 7.5 | H23: =M$1 -> 35 | I23: =E$1 -> 2000 | J23: 22 | K23: =J23*0.8 -> 17.6
B24: =D24*C$14 -> 61.630435 | D24: =E24*F24*G24*H24/(I24*J24) -> 20.543478 | E24: 60 | F24: 60 | G24: 7.5 | H24: =M$1 -> 35 | I24: =E$1 -> 2000 | J24: 23 | K24: =J24*0.8 -> 18.4
B25: =D25*C$14 -> 59.0625 | D25: =E25*F25*G25*H25/(I25*J25) -> 19.6875 | E25: 60 | F25: 60 | G25: 7.5 | H25: =M$1 -> 35 | I25: =E$1 -> 2000 | J25: 24 | K25: =J25*0.8 -> 19.2
B26: =D26*C$14 -> 56.7 | D26: =E26*F26*G26*H26/(I26*J26) -> 18.9 | E26: 60 | F26: 60 | G26: 7.5 | H26: =M$1 -> 35 | I26: =E$1 -> 2000 | J26: 25 | K26: =J26*0.8 -> 20
... B34: =D34*C$14 -> 42.954545 | D34: =E34*F34*G34*H34/(I34*J34) -> 14.318182 | E34: 60 | F34: 60 | G34: 7.5 | H34: =M$1 -> 35 | I34: =E$1 -> 2000 | J34: 33 | K34: =J34*0.8 -> 26.4

Sheet Masterdata
W1: SEMI - TOTAL | X1: =COUNT(O246:O783) -> 538 | Y1: REG | Z1: =COUNT(W246:W783) -> 88 | AD1: =Z1/X1 -> 0.16356877 | AG1: GN | AH1: =COUNT(A4:A237) -> 234 | AI1: REG | AJ1: =COUNT(AE4:AE237) -> 43 | AK1: =AJ1/AH1 -> 0.18376068
A2: 338 | D2: Con mi pad no lo hace | X2: Semiautomáticas
A3: 7 | B3: Estado | C3: Maquina | D3: ARTICULO | E3: UN por CAJA | F3: PESO BR. | G3: PESO NET. | H3: % SCRAP | I3: MATERIAL | J3: MATERIAL DETALLE | K3: CAJAS | L3: BOLSA | M3: Paquete por Caja | N3: Unidades por Paquete | O3: CAV | P3: META | Q3: CICLO Master Darta | R3: Cajas en 8 Horas | S3: Cajas x hora | T3: Cajas x hora | U3: Turnos para fabricar 1000 cajas | V3: Cajas que se fabricarían con las planchas | W3: Seg/ciclo | X3: META | Y3: FECHA | Z3: Registrado por | AD3: FECHA | AE3: MAQ | AF3: Calentamiento | AG3: Ventilador de calor | AH3: Fomación | AI3: Ventilador de forma | AJ3: intervalo de corte | AK3: Retraso de expulsión | AL3: Expulsión | AM3: Transporte | AN3: Retraso de cierre | AO3: Promedio de ciclo | AP3: Molde | AQ3: Zona1 | AR3: Zona2 | AS3: Zona3 | AT3: Precalentador | AU3: Presión de calentamiento | AV3: Presión de formación | AW3: Presión de expusión | AX3: Velocidad | AY3: Recorrido | AZ3: Modo | BA3: Acel/ Desacel | BB3: Velocidad del paso | BC3: Zona4 | BD3: Zona5 | BF3: Registrado por | BG3: FECHA | BH3: MAQ | BI3: Calentamiento | BJ3: Ventilador de calor | BK3: Fomación | BL3: Ventilador de forma | BM3: intervalo de corte | BN3: Retraso de expulsión | BO3: Expulsión | BP3: Transporte | BQ3: Retraso de cierre | BR3: Promedio de ciclo | BS3: Molde | BT3: Zona1 | BU3: Zona2 | BV3: Zona3 | BW3: Precalentador | BX3: Presión de calentamiento | BY3: Presión de formación | BZ3: Presión de expusión | CA3: Velocidad | CB3: Recorrido | CC3: Modo | CD3: Acel/ Desacel | CE3: Velocidad del paso | CF3: Zona4 | CG3: Zona5 | CH3: ZONA | CI3: CANTIDAD X PALLET
A4: 338 | B4: Venta Normal | C4: GN | D4: AP-12 | E4: 1200 | F4: 0.0162 | G4: 0.0135 | H4: =(F4-G4)/F4 -> 0.16666667 | I4: PET | J4: PET CRISTAL 580 x 250 | K4: CAJA Nº 4/1 SIN LOGO | L4: BOLSAS DE 120 X 125 | M4: 6 paq de 174 + 1 paq de 156 unid | O4: 6 | P4: 17 | Q4: =IFERROR(IF(AO4>1,AO4,60*60*8*O4/P4/E4),"") -> 6.3 | R4: =IFERROR(60*60*8*O4/E4/Q4,"") -> 22.857143 | S4: =IFERROR(R4/8,"") -> 2.8571429 | T4: =IFERROR(IF(R4>2,S4,""),"") -> 2.8571429 | AD4: 45612 | AE4: 12 | AF4: 1.6 | AG4: 0.3 | AH4: 1.6 | AI4: 0.4 | AJ4: 0.12 | AK4: 0.18 | AL4: 0.7 | AM4: 0.6 | AN4: 0.3 | AO4: 6.3 | AP4: 56 | AQ4: 110 | AR4: 115 | AS4: 110 | AT4: 37 | AU4: 30 | AV4: 35 | AW4: 42 | AX4: 51 | AY4: 451 | AZ4: Normal | BA4: 2000 | BB4: 14 | CH4: 5 | CI4: 78
A5: 398 | B5: Venta Normal | C5: GN | D5: AP-6 | E5: 1600 | F5: 0.0128 | G5: 0.0103 | H5: =(F5-G5)/F5 -> 0.1953125 | I5: PET | J5: PET CRISTAL 520 x 220 | K5: CAJA Nº 4/1 SIN LOGO | L5: BOLSAS DE 120 X 125 | O5: 6 | P5: 12 | Q5: 6.3 | R5: =IFERROR(60*60*8*O5/E5/Q5,"") -> 17.142857 | S5: =IFERROR(R5/8,"") -> 2.1428571 | T5: =IFERROR(IF(R5>2,S5,""),"") -> 2.1428571 | AD5: 45622 | AE5: 12 | AF5: 1.7 | AG5: 0.5 | AH5: 1.5 | AI5: 0.5 | AJ5: 0.17 | AK5: 0.25 | AL5: 0.5 | AM5: 0.6 | AN5: 0.45 | AO5: 6.6 | AP5: 46 | AQ5: 104 | AR5: 105 | AS5: 105 | AT5: 45 | AU5: 30 | AV5: 35 | AW5: 42 | AX5: 51 | AY5: 459 | AZ5: Normal | BA5: 1400 | BB5: 14 | CH5: 1 | CI5: 41
A6: 723 | B6: Venta Normal | C6: GN | D6: ART. 1445 | E6: 1320 | F6: 0.0084 | G6: 0.0063 | H6: =(F6-G6)/F6 -> 0.25 | I6: PVC | J6: PVC CRISTAL 500 x 300 | K6: CAJA Nº 3 | L6: BOLSAS DE 120 X 80 | O6: 12 | P6: 18 | Q6: =IFERROR(IF(AO6>1,AO6,60*60*8*O6/P6/E6),"") -> 14.545455 | R6: =IFERROR(60*60*8*O6/E6/Q6,"") -> 18 | S6: =IFERROR(R6/8,"") -> 2.25 | T6: =IFERROR(IF(R6>2,S6,""),"") -> 2.25 | CH6: 1 | CI6: 44
A7: 724 | B7: Discontinuado | C7: GN | D7: ART. 1445 OPS | E7: 1320 | F7: 0.0074 | G7: 0.0056 | H7: =(F7-G7)/F7 -> 0.24324324 | I7: OPS | J7: UNICLEAR CRISTAL OPS 480 x 400 | K7: CAJA Nº 3 | L7: BOLSAS DE 120 X 80 | O7: 12 | Q7: =IFERROR(IF(AO7>1,AO7,60*60*8*O7/P7/E7),"") | R7: =IFERROR(60*60*8*O7/E7/Q7,"") | S7: =IFERROR(R7/8,"") | T7: =IFERROR(IF(R7>2,S7,""),"") | CH7: 5 | CI7: 53
A8: 1909 | B8: Venta Normal | C8: GN | D8: ART. 1510 | E8: 400 | F8: 0.0109 | G8: 0.0084 | H8: =(F8-G8)/F8 -> 0.2293578 | I8: PVC | J8: PVC CRISTAL 460 x 300 | K8: CAJA Nº 2 | L8: BOLSAS DE 120 X 80 | O8: 9 | P8: 90 | Q8: =IFERROR(IF(AO8>1,AO8,60*60*8*O8/P8/E8),"") -> 5 | R8: =IFERROR(60*60*8*O8/E8/Q8,"") -> 129.6 | S8: =IFERROR(R8/8,"") -> 16.2 | T8: =IFERROR(IF(R8>2,S8,""),"") -> 16.2 | AD8: 45519 | AE8: 14 | AF8: 1 | AG8: 0.1 | AH8: 1 | AI8: 0.2 | AJ8: 0.75 | AK8: 0.15 | AL8: 0.19 | AM8: 0.75 | AN8: 0.4 | AO8: 5 | AP8: 58 | AQ8: 110 | AR8: 112 | AS8: 112 | AT8: 40 | AU8: 20 | AV8: 40 | AW8: 20 | AX8: 70 | AY8: 465 | AZ8: Normal | BA8: 1100 | BB8: 10 | CH8: 3 | CI8: 82
A9: 1934 | B9: Venta Normal | C9: GN | D9: ART. 1510 NEGRO | E9: 400 | F9: 0.01 | G9: 0.0068 | H9: =(F9-G9)/F9 -> 0.32 | I9: PVC | J9: PAI NEGRO 460 x 350 | K9: CAJA Nº 2 | L9: BOLSAS DE 120 X 80 | M9: 4 | N9: 100 | O9: 9 | P9: 25 | Q9: =IFERROR(IF(AO9>1,AO9,60*60*8*O9/P9/E9),"") -> 25.92 | R9: =IFERROR(60*60*8*O9/E9/Q9,"") -> 25 | S9: =IFERROR(R9/8,"") -> 3.125 | T9: =IFERROR(IF(R9>2,S9,""),"") -> 3.125 | CH9: 3 | CI9: 77
A10: 727 | B10: Venta Normal | C10: GN | D10: ART. 1510 OPS | E10: 800 | F10: 0.0086 | G10: 0.006 | H10: =(F10-G10)/F10 -> 0.30232558 | I10: OPS | J10: UNICLEAR CRISTAL OPS 460 x 300 | K10: CAJA Nº 12 | L10: BOLSAS DE 120 X 110 | O10: 9 | P10: 20 | Q10: =IFERROR(IF(AO10>1,AO10,60*60*8*O10/P10/E10),"") -> 16.2 | R10: =IFERROR(60*60*8*O10/E10/Q10,"") -> 20 | S10: =IFERROR(R10/8,"") -> 2.5 | T10: =IFERROR(IF(R10>2,S10,""),"") -> 2.5 | CH10: 3 | CI10: 59
A11: 728 | B11: Venta Normal | C11: GN | D11: ART. 1510 PAI NEGRO | E11: 800 | F11: 0.0131 | G11: 0.0068 | H11: =(F11-G11)/F11 -> 0.48091603 | I11: HIPST | J11: PAI NEGRO 600 x 350 | K11: CAJA Nº 12 | L11: BOLSAS DE 120 X 110 | O11: 9 | P11: 20 | Q11: =IFERROR(IF(AO11>1,AO11,60*60*8*O11/P11/E11),"") -> 16.2 | R11: =IFERROR(60*60*8*O11/E11/Q11,"") -> 20 | S11: =IFERROR(R11/8,"") -> 2.5 | T11: =IFERROR(IF(R11>2,S11,""),"") -> 2.5 | CH11: 3 | CI11: 60
A12: 1910 | B12: Venta Normal | C12: GN | D12: ART. 1550 | E12: 400 | F12: 0.0146 | G12: 0.0105 | H12: =(F12-G12)/F12 -> 0.28082192 | I12: PVC | J12: PVC CRISTAL 460 x 400 | K12: CAJA Nº 2 | L12: BOLSAS DE 120 X 80 | O12: 9 | P12: 70 | Q12: =IFERROR(IF(AO12>1,AO12,60*60*8*O12/P12/E12),"") -> 6.6 | R12: =IFERROR(60*60*8*O12/E12/Q12,"") -> 98.181818 | S12: =IFERROR(R12/8,"") -> 12.272727 | T12: =IFERROR(IF(R12>2,S12,""),"") -> 12.272727 | AD12: 45519 | AE12: 14 | AF12: 1.4 | AG12: 0.4 | AH12: 1.4 | AI12: 0.4 | AJ12: 1 | AK12: 0.15 | AL12: 0.19 | AM12: 0.6 | AN12: 0.4 | AO12: 6.6 | AP12: 58 | AQ12: 109 | AR12: 109 | AS12: 109 | AT12: 40 | AU12: 20 | AV12: 40 | AW12: 20 | AX12: 7' | AY12: 465 | AZ12: Normal | BA12: 1100 | BB12: 10 | CH12: 1 | CI12: 75
A13: 726 | B13: Venta Normal | C13: GN | D13: ART. 1550 OPS | E13: 800 | F13: 0.0115 | G13: 0.008 | H13: =(F13-G13)/F13 -> 0.30434783 | I13: OPS | J13: DEXTON PS 825EH | K13: CAJA Nº 4/1 | L13: BOLSAS DE 120 X 125 | O13: 9 | P13: 24 | Q13: =IFERROR(IF(AO13>1,AO13,60*60*8*O13/P13/E13),"") -> 13.5 | R13: =IFERROR(60*60*8*O13/E13/Q13,"") -> 24 | S13: =IFERROR(R13/8,"") -> 3 | T13: =IFERROR(IF(R13>2,S13,""),"") -> 3 | CH13: 4 | CI13: 77
A14: 1914 | B14: Venta Normal | C14: GN | D14: ART. 1560 | E14: 300 | F14: 0.0262 | G14: 0.0214 | H14: =(F14-G14)/F14 -> 0.18320611 | I14: PVC | J14: PVC CRISTAL 575 x 250 | K14: CAJA Nº 2 | L14: BOLSAS DE 120 X 80 | M14: 1 | N14: 300 | O14: 3 | P14: 45 | Q14: =IFERROR(IF(AO14>1,AO14,60*60*8*O14/P14/E14),"") -> 4.4 | R14: =IFERROR(60*60*8*O14/E14/Q14,"") -> 65.454545 | S14: =IFERROR(R14/8,"") -> 8.1818182 | T14: =IFERROR(IF(R14>2,S14,""),"") -> 8.1818182 | AD14: 45538 | AE14: 15 | AF14: 0.9 | AG14: 0.2 | AH14: 1 | AI14: 0.2 | AJ14: 0.55 | AK14: 0.17 | AL14: 0.17 | AM14: 0.4 | AN14: 0.3 | AO14: 4.4 | AP14: 61 | AQ14: 103 | AR14: 103 | AS14: 103 | AT14: 38 | AU14: 20 | AV14: 40 | AW14: 20 | AX14: 100 | AY14: 365 | AZ14: Normal | BA14: 1500 | BB14: 10 | BE14: =AO14/4.5-1 -> -0.022222222 | BF14: 20/3/2024 / 22/7/24 | BG14: 13/15 | BH14: 1 / 1,5 | BI14: 0,1 / 0,2 | BJ14: 1,1 /1,3 | BK14: 0,1 / 0,2 | BL14: 0,8 / 1,00 | BM14: 0,2 / 0,18 | BN14: 0,22 / 0,15 | BO14: 0,4 / 0,45 | BP14: 0,3 /0,2 | BQ14: 4,5 / 5,6 | BR14: 59 / 62 | BS14: 104 / 103 | BT14: 104 / 103 | BU14: 104 / 103 | BV14: 45 / 38 | BW14: 20 / 20 | BX14: 40 / 40 | BY14: 20 / 20 | BZ14: 100 / 100 | CA14: 359 / 365 | CB14: Normal | CC14: 700 / 1500 | CD14: 10 / 10 | CH14: 6 | CI14: 53
A15: 1825 | B15: Venta Normal | C15: GN | D15: ART. 1560 - OBSOLETO | E15: 500 | F15: 0.0262 | G15: 0.0214 | H15: =(F15-G15)/F15 -> 0.18320611 | I15: PVC | J15: PVC CRISTAL 575 x 250 | K15: CAJA Nº 15 | L15: BOLSAS DE 120 X 110 | O15: 3 | P15: 33 | Q15: =IFERROR(IF(AO15>1,AO15,60*60*8*O15/P15/E15),"") -> 5.2363636 | R15: =IFERROR(60*60*8*O15/E15/Q15,"") -> 33 | S15: =IFERROR(R15/8,"") -> 4.125 | T15: =IFERROR(IF(R15>2,S15,""),"") -> 4.125 | CH15: 6 | CI15: 81
A16: 1813 | B16: Discontinuado | C16: GN | D16: ART. 1560 PVC (300M) | E16: 500 | F16: 0.0311 | G16: 0.0254 | H16: =(F16-G16)/F16 -> 0.18327974 | I16: PVC | J16: PVC CRISTAL 570 x 300 | K16: CAJA Nº 16 | L16: BOLSAS DE 120 X 125 | O16: 3 | Q16: =IFERROR(IF(AO16>1,AO16,60*60*8*O16/P16/E16),"") | R16: =IFERROR(60*60*8*O16/E16/Q16,"") | S16: =IFERROR(R16/8,"") | T16: =IFERROR(IF(R16>2,S16,""),"") | CH16: 4 | CI16: 41
A17: 104 | B17: Venta Normal | C17: GN | D17: ART. 1610 (200) | E17: 200 | F17: 0.0115 | G17: 0.0087 | H17: =(F17-G17)/F17 -> 0.24347826 | I17: PVC | J17: PVC CRISTAL 520 x 250 | O17: 6 | P17: 70 | Q17: =IFERROR(IF(AO17>1,AO17,60*60*8*O17/P17/E17),"") -> 7.9 | R17: =IFERROR(60*60*8*O17/E17/Q17,"") -> 109.36709 | S17: =IFERROR(R17/8,"") -> 13.670886 | T17: =IFERROR(IF(R17>2,S17,""),"") -> 13.670886 | AD17: 45607 | AE17: 14 | AF17: 2 | AG17: 0.45 | AH17: 2.7 | AI17: 0.45 | AJ17: 0.6 | AK17: 0.2 | AL17: 0.14 | AM17: 0.6 | AN17: 0.3 | AO17: 7.9 | AP17: 42 | AQ17: 102 | AR17: 102 | AS17: 102 | AT17: 40 | AU17: 20 | AV17: 40 | AW17: 20 | AX17: 70 | AY17: 360 | AZ17: Normal | BA17: 900 | BB17: 10 | CH17: 3 | CI17: 86
A18: 43 | B18: Discontinuado | C18: GN | D18: ART. 1610 OPS | E18: 300 | F18: 0.0091 | G18: 0.0064 | H18: =(F18-G18)/F18 -> 0.2967033 | I18: OPS | J18: UNICLEAR CRISTAL OPS 520 x 250 | K18: CAJA Nº 14 | L18: BOLSAS DE 120 X 110 | O18: 6 | Q18: =IFERROR(IF(AO18>1,AO18,60*60*8*O18/P18/E18),"") | R18: =IFERROR(60*60*8*O18/E18/Q18,"") | S18: =IFERROR(R18/8,"") | T18: =IFERROR(IF(R18>2,S18,""),"") | CH18: 1 | CI18: 71
A19: 105 | B19: Venta Normal | C19: GN | D19: ART. 1690 (200) | E19: 200 | F19: 0.0231 | G19: 0.0173 | H19: =(F19-G19)/F19 -> 0.25108225 | I19: PVC | J19: PVC CRISTAL 520 x 500 | K19: CAJA Nº 16 | L19: BOLSAS DE 120 X 110 | M19: 4 | N19: 50 | O19: 6 | P19: 46 | Q19: =IFERROR(IF(AO19>1,AO19,60*60*8*O19/P19/E19),"") -> 11.4 | R19: =IFERROR(60*60*8*O19/E19/Q19,"") -> 75.789474 | S19: =IFERROR(R19/8,"") -> 9.4736842 | T19: =IFERROR(IF(R19>2,S19,""),"") -> 9.4736842 | AD19: 45604 | AE19: 13 | AF19: 3.5 | AG19: 0.4 | AH19: 3.7 | AI19: 0.5 | AJ19: 1.2 | AK19: 0.19 | AL19: 0.16 | AM19: 0.9 | AN19: 0.35 | AO19: 11.4 | AP19: 50 | AQ19: 107 | AR19: 107 | AS19: 107 | AT19: 49 | AU19: 20 | AV19: 40 | AW19: 20 | AX19: 65 | AY19: 386 | AZ19: Normal | BA19: 1000 | CH19: 4 | CI19: 37
A20: 113 | B20: Venta Normal | C20: GN | D20: ART. 1690 BASE | E20: 300 | F20: 0.0231 | G20: 0.0173 | H20: =(F20-G20)/F20 -> 0.25108225 | I20: PVC | J20: PVC CRISTAL 520 x 500 | K20: CAJA Nº 15 | L20: BOLSAS DE 120 X 110 | O20: 6 | P20: 26 | Q20: =IFERROR(IF(AO20>1,AO20,60*60*8*O20/P20/E20),"") -> 22.153846 | R20: =IFERROR(60*60*8*O20/E20/Q20,"") -> 26 | S20: =IFERROR(R20/8,"") -> 3.25 | T20: =IFERROR(IF(R20>2,S20,""),"") -> 3.25 | CH20: 6 | CI20: 69
A21: 107 | B21: Venta Normal | C21: GN | D21: ART. 1690 BASE Y TAPA | E21: 200 | F21: 0.0346 | G21: 0.026 | H21: =(F21-G21)/F21 -> 0.24855491 | I21: PVC | J21: PVC CRISTAL 100 x 10000 | O21: 6 | P21: 55 | Q21: =IFERROR(IF(AO21>1,AO21,60*60*8*O21/P21/E21),"") -> 15.709091 | R21: =IFERROR(60*60*8*O21/E21/Q21,"") -> 55 | S21: =IFERROR(R21/8,"") -> 6.875 | T21: =IFERROR(IF(R21>2,S21,""),"") -> 6.875 | CH21: 5 | CI21: 33
A22: 44 | B22: Venta Normal | C22: GN | D22: ART. 1690 OPS | E22: 300 | F22: 0.0217 | G22: 0.015 | H22: =(F22-G22)/F22 -> 0.30875576 | I22: OPS | J22: UNICLEAR CRISTAL OPS 520 x 600 | K22: CAJA Nº 15 | L22: BOLSAS DE 120 X 110 | O22: 6 | P22: 40 | Q22: =IFERROR(IF(AO22>1,AO22,60*60*8*O22/P22/E22),"") -> 14.4 | R22: =IFERROR(60*60*8*O22/E22/Q22,"") -> 40 | S22: =IFERROR(R22/8,"") -> 5 | T22: =IFERROR(IF(R22>2,S22,""),"") -> 5 | CH22: 6 | CI22: 43
A23: 1911 | B23: Venta Normal | C23: GN | D23: ART. 1810 | E23: 300 | F23: 0.0168 | G23: 0.013 | H23: =(F23-G23)/F23 -> 0.22619048 | I23: PVC | J23: PVC CRISTAL 380 x 300 | K23: CAJA Nº 2 | L23: BOLSAS DE 120 X 80 | O23: 4 | P23: 25 | Q23: =IFERROR(IF(AO23>1,AO23,60*60*8*O23/P23/E23),"") -> 15.36 | R23: =IFERROR(60*60*8*O23/E23/Q23,"") -> 25 | S23: =IFERROR(R23/8,"") -> 3.125 | T23: =IFERROR(IF(R23>2,S23,""),"") -> 3.125 | CH23: 5 | CI23: 44
A24: 1935 | B24: Venta Normal | C24: GN | D24: ART. 1810 NEGRO | E24: 300 | F24: 0.0154 | G24: 0.0105 | H24: =(F24-G24)/F24 -> 0.31818182 | I24: PVC | J24: PAI NEGRO 380 x 350 | K24: CAJA Nº 2 | L24: BOLSAS DE 120 X 80 | O24: 4 | P24: 30 | Q24: =IFERROR(IF(AO24>1,AO24,60*60*8*O24/P24/E24),"") -> 12.8 | R24: =IFERROR(60*60*8*O24/E24/Q24,"") -> 30 | S24: =IFERROR(R24/8,"") -> 3.75 | T24: =IFERROR(IF(R24>2,S24,""),"") -> 3.75 | CH24: 5 | CI24: 71
A25: 731 | B25: Venta Normal | C25: GN | D25: ART. 1810 OPS | E25: 540 | F25: 0.0132 | G25: 0.0094 | H25: =(F25-G25)/F25 -> 0.28787879 | I25: OPS | J25: UNICLEAR CRISTAL OPS 455 x 400 | K25: CAJA Nº 4/1 | L25: BOLSAS DE 120 X 125 | O25: 4 | P25: 28 | Q25: =IFERROR(IF(AO25>1,AO25,60*60*8*O25/P25/E25),"") -> 7.6190476 | R25: =IFERROR(60*60*8*O25/E25/Q25,"") -> 28 | S25: =IFERROR(R25/8,"") -> 3.5 | T25: =IFERROR(IF(R25>2,S25,""),"") -> 3.5 | CH25: 4 | CI25: 90
A26: 732 | B26: Venta Normal | C26: GN | D26: ART. 1810 PAI NEGRO | E26: 540 | F26: 0.0243 | G26: 0.0105 | H26: =(F26-G26)/F26 -> 0.56790123 | I26: HIPST | J26: PAI NEGRO 600 x 350 | K26: CAJA Nº 4/1 | L26: BOLSAS DE 120 X 125 | O26: 4 | P26: 28 | Q26: =IFERROR(IF(AO26>1,AO26,60*60*8*O26/P26/E26),"") -> 7.6190476 | R26: =IFERROR(60*60*8*O26/E26/Q26,"") -> 28 | S26: =IFERROR(R26/8,"") -> 3.5 | T26: =IFERROR(IF(R26>2,S26,""),"") -> 3.5 | CH26: 5 | CI26: 72
A27: 1912 | B27: Venta Normal | C27: GN | D27: ART. 1845 | E27: 300 | F27: 0.0223 | G27: 0.0162 | H27: =(F27-G27)/F27 -> 0.2735426 | I27: PVC | J27: PVC CRISTAL 380 x 400 | K27: CAJA Nº 15 | L27: BOLSAS DE 120 X 110 | O27: 4 | P27: 25 | Q27: =IFERROR(IF(AO27>1,AO27,60*60*8*O27/P27/E27),"") -> 15.36 | R27: =IFERROR(60*60*8*O27/E27/Q27,"") -> 25 | S27: =IFERROR(R27/8,"") -> 3.125 | T27: =IFERROR(IF(R27>2,S27,""),"") -> 3.125 | CH27: 1 | CI27: 40
A28: 729 | B28: Venta Normal | C28: GN | D28: ART. 1845 OPS | E28: 540 | F28: 0.0176 | G28: 0.0128 | H28: =(F28-G28)/F28 -> 0.27272727 | I28: OPS | J28: UNICLEAR CRISTAL OPS 380 x 400 | K28: CAJA Nº 4/1 | L28: BOLSAS DE 120 X 125 | O28: 4 | P28: 30 | Q28: =IFERROR(IF(AO28>1,AO28,60*60*8*O28/P28/E28),"") -> 7.1111111 | R28: =IFERROR(60*60*8*O28/E28/Q28,"") -> 30 | S28: =IFERROR(R28/8,"") -> 3.75 | T28: =IFERROR(IF(R28>2,S28,""),"") -> 3.75 | CH28: 4 | CI28: 60
A29: 1913 | B29: Venta Normal | C29: GN | D29: ART. 1860 | E29: 300 | F29: 0.0251 | G29: 0.0182 | H29: =(F29-G29)/F29 -> 0.2749004 | I29: PVC | J29: PVC CRISTAL 380 x 450 | K29: CAJA Nº 15 | L29: BOLSAS DE 120 X 110 | O29: 4 | P29: 25 | Q29: =IFERROR(IF(AO29>1,AO29,60*60*8*O29/P29/E29),"") -> 15.36 | R29: =IFERROR(60*60*8*O29/E29/Q29,"") -> 25 | S29: =IFERROR(R29/8,"") -> 3.125 | T29: =IFERROR(IF(R29>2,S29,""),"") -> 3.125 | CH29: 5 | CI29: 41
A30: 730 | B30: Venta Normal | C30: GN | D30: ART. 1860 OPS | E30: 540 | F30: 0.0198 | G30: 0.0155 | H30: =(F30-G30)/F30 -> 0.21717172 | I30: OPS | J30: DEXTON PS945EH | K30: CAJA Nº 4/1 | L30: BOLSAS DE 120 X 125 | O30: 4 | P30: 28 | Q30: =IFERROR(IF(AO30>1,AO30,60*60*8*O30/P30/E30),"") -> 7.6190476 | R30: =IFERROR(60*60*8*O30/E30/Q30,"") -> 28 | S30: =IFERROR(R30/8,"") -> 3.5 | T30: =IFERROR(IF(R30>2,S30,""),"") -> 3.5 | CH30: 3 | CI30: 55
A31: 1814 | B31: Venta Normal | C31: GN | D31: ART. 2050 | E31: 520 | F31: 0.025 | G31: 0.0204 | H31: =(F31-G31)/F31 -> 0.184 | I31: PET | J31: PET CRISTAL 460 x 250 | K31: CAJA Nº 12 | L31: BOLSAS DE 120 X 110 | O31: 2 | P31: 34 | Q31: =IFERROR(IF(AO31>1,AO31,60*60*8*O31/P31/E31),"") -> 3.2579186 | R31: =IFERROR(60*60*8*O31/E31/Q31,"") -> 34 | S31: =IFERROR(R31/8,"") -> 4.25 | T31: =IFERROR(IF(R31>2,S31,""),"") -> 4.25 | CH31: 5 | CI31: 52
A32: 1915 | B32: Venta Normal | C32: GN | D32: ART. 2050 (X 300) | E32: 300 | F32: 0.025 | G32: 0.0204 | H32: =(F32-G32)/F32 -> 0.184 | I32: PET | J32: PET CRISTAL 460 x 250 | K32: CAJA Nº 1/2 | L32: BOLSAS DE 120 X 80 | M32: 1 | N32: 300 | O32: 2 | P32: 45 | Q32: =IFERROR(IF(AO32>1,AO32,60*60*8*O32/P32/E32),"") -> 4 | R32: =IFERROR(60*60*8*O32/E32/Q32,"") -> 48 | S32: =IFERROR(R32/8,"") -> 6 | T32: =IFERROR(IF(R32>2,S32,""),"") -> 6 | AD32: 45411 | AE32: 16 | AF32: 0.9 | AG32: 0.1 | AH32: 1 | AI32: 0.1 | AJ32: 0.3 | AK32: 0.36 | AL32: 0.2 | AM32: 0.14 | AN32: 0.5 | AO32: 4 | AP32: 45 | AQ32: 104 | AR32: 109 | AS32: 114 | AT32: 40 | AY32: 383 | BC32: 111 | BD32: 112 | CH32: 5 | CI32: 53
A33: 1815 | B33: Venta Normal | C33: GN | D33: ART. 2060 | E33: 520 | F33: 0.025 | G33: 0.0204 | H33: =(F33-G33)/F33 -> 0.184 | I33: PET | J33: PET CRISTAL 460 x 250 | K33: CAJA Nº 12 | L33: BOLSAS DE 120 X 110 | O33: 2 | P33: 34 | Q33: =IFERROR(IF(AO33>1,AO33,60*60*8*O33/P33/E33),"") -> 3.2579186 | R33: =IFERROR(60*60*8*O33/E33/Q33,"") -> 34 | S33: =IFERROR(R33/8,"") -> 4.25 | T33: =IFERROR(IF(R33>2,S33,""),"") -> 4.25 | CH33: 5 | CI33: 30
A34: 1916 | B34: Venta Normal | C34: GN | D34: ART. 2060 (X 300) | E34: 300 | F34: 0.025 | G34: 0.0204 | H34: =(F34-G34)/F34 -> 0.184 | I34: PET | J34: PET CRISTAL 460 x 250 | K34: CAJA Nº 1/2 | L34: BOLSAS DE 120 X 80 | M34: 1 | N34: 300 | O34: 2 | P34: 50 | Q34: =IFERROR(IF(AO34>1,AO34,60*60*8*O34/P34/E34),"") -> 3.6 | R34: =IFERROR(60*60*8*O34/E34/Q34,"") -> 53.333333 | S34: =IFERROR(R34/8,"") -> 6.6666667 | T34: =IFERROR(IF(R34>2,S34,""),"") -> 6.6666667 | U34: =1000/R34 -> 18.75 | V34: =R34*0.85 -> 45.333333 | AD34: 45378 | AE34: 14 / 15 | AF34: 0.8 | AG34: 0.1 | AH34: 1 | AI34: 0.13 | AJ34: 0.25 | AK34: 0.14 | AL34: 0.21 | AM34: 0.3 | AN34: 0.2 | AO34: 3.6 | AP34: 48 | AQ34: 103 | AR34: 103 | AS34: 103 | AT34: 40 | AU34: 20 | AV34: 40 | AW34: 20 | AX34: 100 | AY34: 294 | AZ34: Normal | BA34: 1200 | BB34: 10 | CH34: 2 | CI34: 44
A35: 1138 | B35: Venta Normal | C35: GN | D35: ART. 2060 (X 300) (DISCONTINUADO) | E35: 300 | F35: 0.025 | G35: 0.0204 | H35: =(F35-G35)/F35 -> 0.184 | I35: PET | J35: PET CRISTAL 460 x 250 | K35: CAJA Nº 1/2 | L35: BOLSAS DE 120 X 80 | O35: 2 | P35: 45 | Q35: =IFERROR(IF(AO35>1,AO35,60*60*8*O35/P35/E35),"") -> 4.2666667 | R35: =IFERROR(60*60*8*O35/E35/Q35,"") -> 45 | S35: =IFERROR(R35/8,"") -> 5.625 | T35: =IFERROR(IF(R35>2,S35,""),"") -> 5.625 | CH35: 6 | CI35: 80
A36: 1816 | B36: Venta Normal | C36: GN | D36: ART. 2060 MPH | E36: 520 | F36: 0.025 | G36: 0.0204 | H36: =(F36-G36)/F36 -> 0.184 | I36: PVC | J36: PVC CRISTAL 460 x 250 | K36: CAJA Nº 4/1 | L36: BOLSAS DE 120 X 125 | O36: 2 | P36: 28 | Q36: =IFERROR(IF(AO36>1,AO36,60*60*8*O36/P36/E36),"") -> 3.956044 | R36: =IFERROR(60*60*8*O36/E36/Q36,"") -> 28 | S36: =IFERROR(R36/8,"") -> 3.5 | T36: =IFERROR(IF(R36>2,S36,""),"") -> 3.5 | CH36: 2 | CI36: 32
A37: 2079 | B37: Venta Normal | C37: GN | D37: ART. 2060 MPH | E37: 200 | F37: 0.025 | G37: 0.0204 | H37: =(F37-G37)/F37 -> 0.184 | I37: PVC | J37: PVC CRISTAL 460 x 250 | K37: CAJA Nº 1/2 | L37: BOLSAS DE 120 X 80 | O37: 2 | P37: 73 | Q37: =IFERROR(IF(AO37>1,AO37,60*60*8*O37/P37/E37),"") -> 3.9452055 | R37: =IFERROR(60*60*8*O37/E37/Q37,"") -> 73 | S37: =IFERROR(R37/8,"") -> 9.125 | T37: =IFERROR(IF(R37>2,S37,""),"") -> 9.125 | CH37: 2 | CI37: 57
A38: 1817 | B38: Venta Normal | C38: GN | D38: ART. 2075 | E38: 200 | F38: 0.0403 | G38: 0.0348 | H38: =(F38-G38)/F38 -> 0.13647643 | I38: PVC | J38: PVC CRISTAL 480 x 250 | K38: CAJA Nº 4/1 | L38: BOLSAS DE 120 X 125 | O38: 2 | P38: 40 | Q38: =IFERROR(IF(AO38>1,AO38,60*60*8*O38/P38/E38),"") -> 7.2 | R38: =IFERROR(60*60*8*O38/E38/Q38,"") -> 40 | S38: =IFERROR(R38/8,"") -> 5 | T38: =IFERROR(IF(R38>2,S38,""),"") -> 5 | CH38: 6 | CI38: 82
A39: 1818 | B39: Venta Normal | C39: GN | D39: ART. 2095 | E39: 200 | F39: 0.0299 | G39: 0.0247 | H39: =(F39-G39)/F39 -> 0.17391304 | I39: PVC | J39: PVC CRISTAL 460 x 300 | K39: CAJA Nº 1/2 | L39: BOLSAS DE 120 X 80 | M39: 1 | N39: 200 | O39: 2 | P39: 58 | Q39: =IFERROR(IF(AO39>1,AO39,60*60*8*O39/P39/E39),"") -> 4.6 | R39: =IFERROR(60*60*8*O39/E39/Q39,"") -> 62.608696 | S39: =IFERROR(R39/8,"") -> 7.826087 | T39: =IFERROR(IF(R39>2,S39,""),"") -> 7.826087 | Z39: Christian | AD39: 45391 | AE39: 15 | AF39: 1 | AG39: 0.1 | AH39: 1 | AI39: 0.1 | AJ39: 0.5 | AK39: 0.2 | AL39: 0.16 | AM39: 0.7 | AN39: 0.3 | AO39: 4.6 | AP39: 45 | AQ39: 106 | AR39: 106 | AS39: 106 | AT39: 50 | AU39: 20 | AV39: 40 | AW39: 20 | AX39: 100 | AY39: 297 | AZ39: Normal | BA39: 1000 | BB39: 10 | CH39: 3 | CI39: 52
A40: 1819 | B40: Venta Normal | C40: GN | D40: ART. 2450 | E40: 360 | F40: 0.0343 | G40: 0.0283 | H40: =(F40-G40)/F40 -> 0.17492711 | I40: PVC | J40: PVC CRISTAL 560 x 250 | K40: CAJA Nº 17 | L40: BOLSAS DE 120 X 110 | M40: 2 | N40: 180 | O40: 2 | P40: 41 | Q40: =IFERROR(IF(AO40>1,AO40,60*60*8*O40/P40/E40),"") -> 3.6 | R40: =IFERROR(60*60*8*O40/E40/Q40,"") -> 44.444444 | S40: =IFERROR(R40/8,"") -> 5.5555556 | T40: =IFERROR(IF(R40>2,S40,""),"") -> 5.5555556 | Z40: Christian | AD40: 45504 | AE40: 12 | AF40: 0.8 | AG40: 0.15 | AH40: 0.8 | AI40: 0.15 | AJ40: 0.4 | AK40: 0.12 | AL40: 0.16 | AM40: 0.33 | AN40: 0.15 | AO40: 3.6 | AP40: 51 | AQ40: 104 | AR40: 104 | AS40: 104 | AT40: 40 | AU40: 30 | AV40: 40 | AW40: 40 | AX40: 100 | AY40: 330 | AZ40: Normal | BA40: 2400 | BB40: 10 | CH40: 3 | CI40: 48
...

Sheet Productividad
W1: SEMI - TOTAL | X1: =COUNT(O251:O788) -> 538 | Y1: REG | Z1: =COUNT(W251:W788) -> 88 | AD1: =Z1/X1 -> 0.16356877 | AG1: GN | AH1: =COUNT(A4:A237) -> 234 | AI1: REG | AJ1: =COUNT(AE4:AE237) -> 43 | AK1: =AJ1/AH1 -> 0.18376068
A2: 338 | D2: Con mi pad no lo hace | X2: Semiautomáticas
A3: 25 | B3: Estado | C3: Maquina | D3: ARTICULO | E3: UN por CAJA | F3: PESO BR. | G3: PESO NET. | H3: % SCRAP | I3: MATERIAL | J3: MATERIAL DETALLE | K3: CAJAS | L3: BOLSA | M3: Paquete por Caja | N3: Unidades por Paquete | O3: CAV | P3: META | Q3: CICLO Master Darta | R3: Cajas en 8 Horas | S3: Cajas x hora | T3: Cajas x hora | U3: Turnos para fabricar 1000 cajas | V3: Cajas que se fabricarían con las planchas | W3: Seg/ciclo | X3: META | Y3: FECHA | Z3: Registrado por | AD3: FECHA | AE3: MAQ | AF3: Calentamiento | AG3: Ventilador de calor | AH3: Fomación | AI3: Ventilador de forma | AJ3: intervalo de corte | AK3: Retraso de expulsión | AL3: Expulsión | AM3: Transporte | AN3: Retraso de cierre | AO3: Promedio de ciclo | AP3: Molde | AQ3: Zona1 | AR3: Zona2 | AS3: Zona3 | AT3: Precalentador | AU3: Presión de calentamiento | AV3: Presión de formación | AW3: Presión de expusión | AX3: Velocidad | AY3: Recorrido | AZ3: Modo | BA3: Acel/ Desacel | BB3: Velocidad del paso | BC3: Zona4 | BD3: Zona5 | BF3: Registrado por | BG3: FECHA | BH3: MAQ | BI3: Calentamiento | BJ3: Ventilador de calor | BK3: Fomación | BL3: Ventilador de forma | BM3: intervalo de corte | BN3: Retraso de expulsión | BO3: Expulsión | BP3: Transporte | BQ3: Retraso de cierre | BR3: Promedio de ciclo | BS3: Molde | BT3: Zona1 | BU3: Zona2 | BV3: Zona3 | BW3: Precalentador | BX3: Presión de calentamiento | BY3: Presión de formación | BZ3: Presión de expusión | CA3: Velocidad | CB3: Recorrido | CC3: Modo | CD3: Acel/ Desacel | CE3: Velocidad del paso | CF3: Zona4 | CG3: Zona5 | CH3: Acuerdo
A4: 338 | B4: Venta Normal | C4: GN | D4: AP-12 | E4: 1200 | F4: 0.0162 | G4: 0.0135 | H4: =(F4-G4)/F4 -> 0.16666667 | I4: PET | J4: PET CRISTAL 580 x 250 | K4: CAJA Nº 4/1 SIN LOGO | L4: BOLSAS DE 120 X 125 | M4: 6 paq de 174 + 1 paq de 156 unid | O4: 6 | P4: 17 | Q4: =IFERROR(IF(AO4>1,AO4,60*60*8*O4/P4/E4),"") -> 6.3 | R4: =IFERROR(60*60*8*O4/E4/Q4,"") -> 22.857143 | S4: =IFERROR(R4/8,"") -> 2.8571429 | T4: =IFERROR(IF(R4>2,S4,""),"") -> 2.8571429 | AD4: 45612 | AE4: 12 | AF4: 1.6 | AG4: 0.3 | AH4: 1.6 | AI4: 0.4 | AJ4: 0.12 | AK4: 0.18 | AL4: 0.7 | AM4: 0.6 | AN4: 0.3 | AO4: 6.3 | AP4: 56 | AQ4: 110 | AR4: 115 | AS4: 110 | AT4: 37 | AU4: 30 | AV4: 35 | AW4: 42 | AX4: 51 | AY4: 451 | AZ4: Normal | BA4: 2000 | BB4: 14
A5: 398 | B5: Venta Normal | C5: GN | D5: AP-6 | E5: 1600 | F5: 0.0128 | G5: 0.0103 | H5: =(F5-G5)/F5 -> 0.1953125 | I5: PET | J5: PET CRISTAL 520 x 220 | K5: CAJA Nº 4/1 SIN LOGO | L5: BOLSAS DE 120 X 125 | O5: 6 | P5: 12 | Q5: 6.3 | R5: =IFERROR(60*60*8*O5/E5/Q5,"") -> 17.142857 | S5: =IFERROR(R5/8,"") -> 2.1428571 | T5: =IFERROR(IF(R5>2,S5,""),"") -> 2.1428571 | AD5: 45622 | AE5: 12 | AF5: 1.7 | AG5: 0.5 | AH5: 1.5 | AI5: 0.5 | AJ5: 0.17 | AK5: 0.25 | AL5: 0.5 | AM5: 0.6 | AN5: 0.45 | AO5: 6.6 | AP5: 46 | AQ5: 104 | AR5: 105 | AS5: 105 | AT5: 45 | AU5: 30 | AV5: 35 | AW5: 42 | AX5: 51 | AY5: 459 | AZ5: Normal | BA5: 1400 | BB5: 14
A6: 723 | B6: Venta Normal | C6: GN | D6: ART. 1445 | E6: 1320 | F6: 0.0084 | G6: 0.0063 | H6: =(F6-G6)/F6 -> 0.25 | I6: PVC | J6: PVC CRISTAL 500 x 300 | K6: CAJA Nº 3 | L6: BOLSAS DE 120 X 80 | O6: 12 | P6: 18 | Q6: =IFERROR(IF(AO6>1,AO6,60*60*8*O6/P6/E6),"") -> 14.545455 | R6: =IFERROR(60*60*8*O6/E6/Q6,"") -> 18 | S6: =IFERROR(R6/8,"") -> 2.25 | T6: =IFERROR(IF(R6>2,S6,""),"") -> 2.25
A7: 724 | B7: Discontinuado | C7: GN | D7: ART. 1445 OPS | E7: 1320 | F7: 0.0074 | G7: 0.0056 | H7: =(F7-G7)/F7 -> 0.24324324 | I7: OPS | J7: UNICLEAR CRISTAL OPS 480 x 400 | K7: CAJA Nº 3 | L7: BOLSAS DE 120 X 80 | O7: 12 | Q7: =IFERROR(IF(AO7>1,AO7,60*60*8*O7/P7/E7),"") | R7: =IFERROR(60*60*8*O7/E7/Q7,"") | S7: =IFERROR(R7/8,"") | T7: =IFERROR(IF(R7>2,S7,""),"")
A8: 1909 | B8: Venta Normal | C8: GN | D8: ART. 1510 | E8: 400 | F8: 0.0109 | G8: 0.0084 | H8: =(F8-G8)/F8 -> 0.2293578 | I8: PVC | J8: PVC CRISTAL 460 x 300 | K8: CAJA Nº 2 | L8: BOLSAS DE 120 X 80 | O8: 9 | P8: 90 | Q8: =IFERROR(IF(AO8>1,AO8,60*60*8*O8/P8/E8),"") -> 5 | R8: =IFERROR(60*60*8*O8/E8/Q8,"") -> 129.6 | S8: =IFERROR(R8/8,"") -> 16.2 | T8: =IFERROR(IF(R8>2,S8,""),"") -> 16.2 | AD8: 45519 | AE8: 14 | AF8: 1 | AG8: 0.1 | AH8: 1 | AI8: 0.2 | AJ8: 0.75 | AK8: 0.15 | AL8: 0.19 | AM8: 0.75 | AN8: 0.4 | AO8: 5 | AP8: 58 | AQ8: 110 | AR8: 112 | AS8: 112 | AT8: 40 | AU8: 20 | AV8: 40 | AW8: 20 | AX8: 70 | AY8: 465 | AZ8: Normal | BA8: 1100 | BB8: 10
A9: 1934 | B9: Venta Normal | C9: GN | D9: ART. 1510 NEGRO | E9: 400 | F9: 0.01 | G9: 0.0068 | H9: =(F9-G9)/F9 -> 0.32 | I9: PVC | J9: PAI NEGRO 460 x 350 | K9: CAJA Nº 2 | L9: BOLSAS DE 120 X 80 | M9: 4 | N9: 100 | O9: 9 | P9: 25 | Q9: =IFERROR(IF(AO9>1,AO9,60*60*8*O9/P9/E9),"") -> 25.92 | R9: =IFERROR(60*60*8*O9/E9/Q9,"") -> 25 | S9: =IFERROR(R9/8,"") -> 3.125 | T9: =IFERROR(IF(R9>2,S9,""),"") -> 3.125
A10: 727 | B10: Venta Normal | C10: GN | D10: ART. 1510 OPS | E10: 800 | F10: 0.0086 | G10: 0.006 | H10: =(F10-G10)/F10 -> 0.30232558 | I10: OPS | J10: UNICLEAR CRISTAL OPS 460 x 300 | K10: CAJA Nº 12 | L10: BOLSAS DE 120 X 110 | O10: 9 | P10: 20 | Q10: =IFERROR(IF(AO10>1,AO10,60*60*8*O10/P10/E10),"") -> 16.2 | R10: =IFERROR(60*60*8*O10/E10/Q10,"") -> 20 | S10: =IFERROR(R10/8,"") -> 2.5 | T10: =IFERROR(IF(R10>2,S10,""),"") -> 2.5
A11: 728 | B11: Venta Normal | C11: GN | D11: ART. 1510 PAI NEGRO | E11: 800 | F11: 0.0131 | G11: 0.0068 | H11: =(F11-G11)/F11 -> 0.48091603 | I11: HIPST | J11: PAI NEGRO 600 x 350 | K11: CAJA Nº 12 | L11: BOLSAS DE 120 X 110 | O11: 9 | P11: 20 | Q11: =IFERROR(IF(AO11>1,AO11,60*60*8*O11/P11/E11),"") -> 16.2 | R11: =IFERROR(60*60*8*O11/E11/Q11,"") -> 20 | S11: =IFERROR(R11/8,"") -> 2.5 | T11: =IFERROR(IF(R11>2,S11,""),"") -> 2.5
A12: 1910 | B12: Venta Normal | C12: GN | D12: ART. 1550 | E12: 400 | F12: 0.0146 | G12: 0.0105 | H12: =(F12-G12)/F12 -> 0.28082192 | I12: PVC | J12: PVC CRISTAL 460 x 400 | K12: CAJA Nº 2 | L12: BOLSAS DE 120 X 80 | O12: 9 | P12: 70 | Q12: =IFERROR(IF(AO12>1,AO12,60*60*8*O12/P12/E12),"") -> 6.6 | R12: =IFERROR(60*60*8*O12/E12/Q12,"") -> 98.181818 | S12: =IFERROR(R12/8,"") -> 12.272727 | T12: =IFERROR(IF(R12>2,S12,""),"") -> 12.272727 | AD12: 45519 | AE12: 14 | AF12: 1.4 | AG12: 0.4 | AH12: 1.4 | AI12: 0.4 | AJ12: 1 | AK12: 0.15 | AL12: 0.19 | AM12: 0.6 | AN12: 0.4 | AO12: 6.6 | AP12: 58 | AQ12: 109 | AR12: 109 | AS12: 109 | AT12: 40 | AU12: 20 | AV12: 40 | AW12: 20 | AX12: 7' | AY12: 465 | AZ12: Normal | BA12: 1100 | BB12: 10
A13: 726 | B13: Venta Normal | C13: GN | D13: ART. 1550 OPS | E13: 800 | F13: 0.0115 | G13: 0.008 | H13: =(F13-G13)/F13 -> 0.30434783 | I13: OPS | J13: DEXTON PS 825EH | K13: CAJA Nº 4/1 | L13: BOLSAS DE 120 X 125 | O13: 9 | P13: 24 | Q13: =IFERROR(IF(AO13>1,AO13,60*60*8*O13/P13/E13),"") -> 13.5 | R13: =IFERROR(60*60*8*O13/E13/Q13,"") -> 24 | S13: =IFERROR(R13/8,"") -> 3 | T13: =IFERROR(IF(R13>2,S13,""),"") -> 3
A14: 1914 | B14: Venta Normal | C14: GN | D14: ART. 1560 | E14: 300 | F14: 0.0262 | G14: 0.0214 | H14: =(F14-G14)/F14 -> 0.18320611 | I14: PVC | J14: PVC CRISTAL 575 x 250 | K14: CAJA Nº 2 | L14: BOLSAS DE 120 X 80 | M14: 1 | N14: 300 | O14: 3 | P14: 45 | Q14: =IFERROR(IF(AO14>1,AO14,60*60*8*O14/P14/E14),"") -> 4.4 | R14: =IFERROR(60*60*8*O14/E14/Q14,"") -> 65.454545 | S14: =IFERROR(R14/8,"") -> 8.1818182 | T14: =IFERROR(IF(R14>2,S14,""),"") -> 8.1818182 | AD14: 45538 | AE14: 15 | AF14: 0.9 | AG14: 0.2 | AH14: 1 | AI14: 0.2 | AJ14: 0.55 | AK14: 0.17 | AL14: 0.17 | AM14: 0.4 | AN14: 0.3 | AO14: 4.4 | AP14: 61 | AQ14: 103 | AR14: 103 | AS14: 103 | AT14: 38 | AU14: 20 | AV14: 40 | AW14: 20 | AX14: 100 | AY14: 365 | AZ14: Normal | BA14: 1500 | BB14: 10 | BE14: =AO14/4.5-1 -> -0.022222222 | BF14: 20/3/2024 / 22/7/24 | BG14: 13/15 | BH14: 1 / 1,5 | BI14: 0,1 / 0,2 | BJ14: 1,1 /1,3 | BK14: 0,1 / 0,2 | BL14: 0,8 / 1,00 | BM14: 0,2 / 0,18 | BN14: 0,22 / 0,15 | BO14: 0,4 / 0,45 | BP14: 0,3 /0,2 | BQ14: 4,5 / 5,6 | BR14: 59 / 62 | BS14: 104 / 103 | BT14: 104 / 103 | BU14: 104 / 103 | BV14: 45 / 38 | BW14: 20 / 20 | BX14: 40 / 40 | BY14: 20 / 20 | BZ14: 100 / 100 | CA14: 359 / 365 | CB14: Normal | CC14: 700 / 1500 | CD14: 10 / 10
A15: 1825 | B15: Venta Normal | C15: GN | D15: ART. 1560 - OBSOLETO | E15: 500 | F15: 0.0262 | G15: 0.0214 | H15: =(F15-G15)/F15 -> 0.18320611 | I15: PVC | J15: PVC CRISTAL 575 x 250 | K15: CAJA Nº 15 | L15: BOLSAS DE 120 X 110 | O15: 3 | P15: 33 | Q15: =IFERROR(IF(AO15>1,AO15,60*60*8*O15/P15/E15),"") -> 5.2363636 | R15: =IFERROR(60*60*8*O15/E15/Q15,"") -> 33 | S15: =IFERROR(R15/8,"") -> 4.125 | T15: =IFERROR(IF(R15>2,S15,""),"") -> 4.125
A16: 1813 | B16: Discontinuado | C16: GN | D16: ART. 1560 PVC (300M) | E16: 500 | F16: 0.0311 | G16: 0.0254 | H16: =(F16-G16)/F16 -> 0.18327974 | I16: PVC | J16: PVC CRISTAL 570 x 300 | K16: CAJA Nº 16 | L16: BOLSAS DE 120 X 125 | O16: 3 | Q16: =IFERROR(IF(AO16>1,AO16,60*60*8*O16/P16/E16),"") | R16: =IFERROR(60*60*8*O16/E16/Q16,"") | S16: =IFERROR(R16/8,"") | T16: =IFERROR(IF(R16>2,S16,""),"")
A17: 104 | B17: Venta Normal | C17: GN | D17: ART. 1610 (200) | E17: 200 | F17: 0.0115 | G17: 0.0087 | H17: =(F17-G17)/F17 -> 0.24347826 | I17: PVC | J17: PVC CRISTAL 520 x 250 | O17: 6 | P17: 70 | Q17: =IFERROR(IF(AO17>1,AO17,60*60*8*O17/P17/E17),"") -> 7.9 | R17: =IFERROR(60*60*8*O17/E17/Q17,"") -> 109.36709 | S17: =IFERROR(R17/8,"") -> 13.670886 | T17: =IFERROR(IF(R17>2,S17,""),"") -> 13.670886 | AD17: 45607 | AE17: 14 | AF17: 2 | AG17: 0.45 | AH17: 2.7 | AI17: 0.45 | AJ17: 0.6 | AK17: 0.2 | AL17: 0.14 | AM17: 0.6 | AN17: 0.3 | AO17: 7.9 | AP17: 42 | AQ17: 102 | AR17: 102 | AS17: 102 | AT17: 40 | AU17: 20 | AV17: 40 | AW17: 20 | AX17: 70 | AY17: 360 | AZ17: Normal | BA17: 900 | BB17: 10
A18: 43 | B18: Discontinuado | C18: GN | D18: ART. 1610 OPS | E18: 300 | F18: 0.0091 | G18: 0.0064 | H18: =(F18-G18)/F18 -> 0.2967033 | I18: OPS | J18: UNICLEAR CRISTAL OPS 520 x 250 | K18: CAJA Nº 14 | L18: BOLSAS DE 120 X 110 | O18: 6 | Q18: =IFERROR(IF(AO18>1,AO18,60*60*8*O18/P18/E18),"") | R18: =IFERROR(60*60*8*O18/E18/Q18,"") | S18: =IFERROR(R18/8,"") | T18: =IFERROR(IF(R18>2,S18,""),"")
A19: 105 | B19: Venta Normal | C19: GN | D19: ART. 1690 (200) | E19: 200 | F19: 0.0231 | G19: 0.0173 | H19: =(F19-G19)/F19 -> 0.25108225 | I19: PVC | J19: PVC CRISTAL 520 x 500 | K19: CAJA Nº 16 | L19: BOLSAS DE 120 X 110 | M19: 4 | N19: 50 | O19: 6 | P19: 46 | Q19: =IFERROR(IF(AO19>1,AO19,60*60*8*O19/P19/E19),"") -> 11.4 | R19: =IFERROR(60*60*8*O19/E19/Q19,"") -> 75.789474 | S19: =IFERROR(R19/8,"") -> 9.4736842 | T19: =IFERROR(IF(R19>2,S19,""),"") -> 9.4736842 | AD19: 45604 | AE19: 13 | AF19: 3.5 | AG19: 0.4 | AH19: 3.7 | AI19: 0.5 | AJ19: 1.2 | AK19: 0.19 | AL19: 0.16 | AM19: 0.9 | AN19: 0.35 | AO19: 11.4 | AP19: 50 | AQ19: 107 | AR19: 107 | AS19: 107 | AT19: 49 | AU19: 20 | AV19: 40 | AW19: 20 | AX19: 65 | AY19: 386 | AZ19: Normal | BA19: 1000
A20: 113 | B20: Venta Normal | C20: GN | D20: ART. 1690 BASE | E20: 300 | F20: 0.0231 | G20: 0.0173 | H20: =(F20-G20)/F20 -> 0.25108225 | I20: PVC | J20: PVC CRISTAL 520 x 500 | K20: CAJA Nº 15 | L20: BOLSAS DE 120 X 110 | O20: 6 | P20: 26 | Q20: =IFERROR(IF(AO20>1,AO20,60*60*8*O20/P20/E20),"") -> 22.153846 | R20: =IFERROR(60*60*8*O20/E20/Q20,"") -> 26 | S20: =IFERROR(R20/8,"") -> 3.25 | T20: =IFERROR(IF(R20>2,S20,""),"") -> 3.25
A21: 107 | B21: Venta Normal | C21: GN | D21: ART. 1690 BASE Y TAPA | E21: 200 | F21: 0.0346 | G21: 0.026 | H21: =(F21-G21)/F21 -> 0.24855491 | I21: PVC | J21: PVC CRISTAL 100 x 10000 | O21: 6 | P21: 55 | Q21: =IFERROR(IF(AO21>1,AO21,60*60*8*O21/P21/E21),"") -> 15.709091 | R21: =IFERROR(60*60*8*O21/E21/Q21,"") -> 55 | S21: =IFERROR(R21/8,"") -> 6.875 | T21: =IFERROR(IF(R21>2,S21,""),"") -> 6.875
A22: 44 | B22: Venta Normal | C22: GN | D22: ART. 1690 OPS | E22: 300 | F22: 0.0217 | G22: 0.015 | H22: =(F22-G22)/F22 -> 0.30875576 | I22: OPS | J22: UNICLEAR CRISTAL OPS 520 x 600 | K22: CAJA Nº 15 | L22: BOLSAS DE 120 X 110 | O22: 6 | P22: 40 | Q22: =IFERROR(IF(AO22>1,AO22,60*60*8*O22/P22/E22),"") -> 14.4 | R22: =IFERROR(60*60*8*O22/E22/Q22,"") -> 40 | S22: =IFERROR(R22/8,"") -> 5 | T22: =IFERROR(IF(R22>2,S22,""),"") -> 5
A23: 1911 | B23: Venta Normal | C23: GN | D23: ART. 1810 | E23: 300 | F23: 0.0168 | G23: 0.013 | H23: =(F23-G23)/F23 -> 0.22619048 | I23: PVC | J23: PVC CRISTAL 380 x 300 | K23: CAJA Nº 2 | L23: BOLSAS DE 120 X 80 | O23: 4 | P23: 25 | Q23: =IFERROR(IF(AO23>1,AO23,60*60*8*O23/P23/E23),"") -> 15.36 | R23: =IFERROR(60*60*8*O23/E23/Q23,"") -> 25 | S23: =IFERROR(R23/8,"") -> 3.125 | T23: =IFERROR(IF(R23>2,S23,""),"") -> 3.125
A24: 1935 | B24: Venta Normal | C24: GN | D24: ART. 1810 NEGRO | E24: 300 | F24: 0.0154 | G24: 0.0105 | H24: =(F24-G24)/F24 -> 0.31818182 | I24: PVC | J24: PAI NEGRO 380 x 350 | K24: CAJA Nº 2 | L24: BOLSAS DE 120 X 80 | O24: 4 | P24: 30 | Q24: =IFERROR(IF(AO24>1,AO24,60*60*8*O24/P24/E24),"") -> 12.8 | R24: =IFERROR(60*60*8*O24/E24/Q24,"") -> 30 | S24: =IFERROR(R24/8,"") -> 3.75 | T24: =IFERROR(IF(R24>2,S24,""),"") -> 3.75
A25: 731 | B25: Venta Normal | C25: GN | D25: ART. 1810 OPS | E25: 540 | F25: 0.0132 | G25: 0.0094 | H25: =(F25-G25)/F25 -> 0.28787879 | I25: OPS | J25: UNICLEAR CRISTAL OPS 455 x 400 | K25: CAJA Nº 4/1 | L25: BOLSAS DE 120 X 125 | O25: 4 | P25: 28 | Q25: =IFERROR(IF(AO25>1,AO25,60*60*8*O25/P25/E25),"") -> 7.6190476 | R25: =IFERROR(60*60*8*O25/E25/Q25,"") -> 28 | S25: =IFERROR(R25/8,"") -> 3.5 | T25: =IFERROR(IF(R25>2,S25,""),"") -> 3.5
A26: 732 | B26: Venta Normal | C26: GN | D26: ART. 1810 PAI NEGRO | E26: 540 | F26: 0.0243 | G26: 0.0105 | H26: =(F26-G26)/F26 -> 0.56790123 | I26: HIPST | J26: PAI NEGRO 600 x 350 | K26: CAJA Nº 4/1 | L26: BOLSAS DE 120 X 125 | O26: 4 | P26: 28 | Q26: =IFERROR(IF(AO26>1,AO26,60*60*8*O26/P26/E26),"") -> 7.6190476 | R26: =IFERROR(60*60*8*O26/E26/Q26,"") -> 28 | S26: =IFERROR(R26/8,"") -> 3.5 | T26: =IFERROR(IF(R26>2,S26,""),"") -> 3.5
A27: 1912 | B27: Venta Normal | C27: GN | D27: ART. 1845 | E27: 300 | F27: 0.0223 | G27: 0.0162 | H27: =(F27-G27)/F27 -> 0.2735426 | I27: PVC | J27: PVC CRISTAL 380 x 400 | K27: CAJA Nº 15 | L27: BOLSAS DE 120 X 110 | O27: 4 | P27: 25 | Q27: =IFERROR(IF(AO27>1,AO27,60*60*8*O27/P27/E27),"") -> 15.36 | R27: =IFERROR(60*60*8*O27/E27/Q27,"") -> 25 | S27: =IFERROR(R27/8,"") -> 3.125 | T27: =IFERROR(IF(R27>2,S27,""),"") -> 3.125
A28: 729 | B28: Venta Normal | C28: GN | D28: ART. 1845 OPS | E28: 540 | F28: 0.0176 | G28: 0.0128 | H28: =(F28-G28)/F28 -> 0.27272727 | I28: OPS | J28: UNICLEAR CRISTAL OPS 380 x 400 | K28: CAJA Nº 4/1 | L28: BOLSAS DE 120 X 125 | O28: 4 | P28: 30 | Q28: =IFERROR(IF(AO28>1,AO28,60*60*8*O28/P28/E28),"") -> 7.1111111 | R28: =IFERROR(60*60*8*O28/E28/Q28,"") -> 30 | S28: =IFERROR(R28/8,"") -> 3.75 | T28: =IFERROR(IF(R28>2,S28,""),"") -> 3.75
A29: 1913 | B29: Venta Normal | C29: GN | D29: ART. 1860 | E29: 300 | F29: 0.0251 | G29: 0.0182 | H29: =(F29-G29)/F29 -> 0.2749004 | I29: PVC | J29: PVC CRISTAL 380 x 450 | K29: CAJA Nº 15 | L29: BOLSAS DE 120 X 110 | O29: 4 | P29: 25 | Q29: =IFERROR(IF(AO29>1,AO29,60*60*8*O29/P29/E29),"") -> 15.36 | R29: =IFERROR(60*60*8*O29/E29/Q29,"") -> 25 | S29: =IFERROR(R29/8,"") -> 3.125 | T29: =IFERROR(IF(R29>2,S29,""),"") -> 3.125
A30: 730 | B30: Venta Normal | C30: GN | D30: ART. 1860 OPS | E30: 540 | F30: 0.0198 | G30: 0.0155 | H30: =(F30-G30)/F30 -> 0.21717172 | I30: OPS | J30: DEXTON PS945EH | K30: CAJA Nº 4/1 | L30: BOLSAS DE 120 X 125 | O30: 4 | P30: 28 | Q30: =IFERROR(IF(AO30>1,AO30,60*60*8*O30/P30/E30),"") -> 7.6190476 | R30: =IFERROR(60*60*8*O30/E30/Q30,"") -> 28 | S30: =IFERROR(R30/8,"") -> 3.5 | T30: =IFERROR(IF(R30>2,S30,""),"") -> 3.5
A31: 1814 | B31: Venta Normal | C31: GN | D31: ART. 2050 | E31: 520 | F31: 0.025 | G31: 0.0204 | H31: =(F31-G31)/F31 -> 0.184 | I31: PET | J31: PET CRISTAL 460 x 250 | K31: CAJA Nº 12 | L31: BOLSAS DE 120 X 110 | O31: 2 | P31: 34 | Q31: =IFERROR(IF(AO31>1,AO31,60*60*8*O31/P31/E31),"") -> 3.2579186 | R31: =IFERROR(60*60*8*O31/E31/Q31,"") -> 34 | S31: =IFERROR(R31/8,"") -> 4.25 | T31: =IFERROR(IF(R31>2,S31,""),"") -> 4.25
A32: 1915 | B32: Venta Normal | C32: GN | D32: ART. 2050 (X 300) | E32: 300 | F32: 0.025 | G32: 0.0204 | H32: =(F32-G32)/F32 -> 0.184 | I32: PET | J32: PET CRISTAL 460 x 250 | K32: CAJA Nº 1/2 | L32: BOLSAS DE 120 X 80 | M32: 1 | N32: 300 | O32: 2 | P32: 45 | Q32: =IFERROR(IF(AO32>1,AO32,60*60*8*O32/P32/E32),"") -> 4 | R32: =IFERROR(60*60*8*O32/E32/Q32,"") -> 48 | S32: =IFERROR(R32/8,"") -> 6 | T32: =IFERROR(IF(R32>2,S32,""),"") -> 6 | AD32: 45411 | AE32: 16 | AF32: 0.9 | AG32: 0.1 | AH32: 1 | AI32: 0.1 | AJ32: 0.3 | AK32: 0.36 | AL32: 0.2 | AM32: 0.14 | AN32: 0.5 | AO32: 4 | AP32: 45 | AQ32: 104 | AR32: 109 | AS32: 114 | AT32: 40 | AY32: 383 | BC32: 111 | BD32: 112
A33: 1815 | B33: Venta Normal | C33: GN | D33: ART. 2060 | E33: 520 | F33: 0.025 | G33: 0.0204 | H33: =(F33-G33)/F33 -> 0.184 | I33: PET | J33: PET CRISTAL 460 x 250 | K33: CAJA Nº 12 | L33: BOLSAS DE 120 X 110 | O33: 2 | P33: 34 | Q33: =IFERROR(IF(AO33>1,AO33,60*60*8*O33/P33/E33),"") -> 3.2579186 | R33: =IFERROR(60*60*8*O33/E33/Q33,"") -> 34 | S33: =IFERROR(R33/8,"") -> 4.25 | T33: =IFERROR(IF(R33>2,S33,""),"") -> 4.25
A34: 1916 | B34: Venta Normal | C34: GN | D34: ART. 2060 (X 300) | E34: 300 | F34: 0.025 | G34: 0.0204 | H34: =(F34-G34)/F34 -> 0.184 | I34: PET | J34: PET CRISTAL 460 x 250 | K34: CAJA Nº 1/2 | L34: BOLSAS DE 120 X 80 | M34: 1 | N34: 300 | O34: 2 | P34: 50 | Q34: =IFERROR(IF(AO34>1,AO34,60*60*8*O34/P34/E34),"") -> 3.6 | R34: =IFERROR(60*60*8*O34/E34/Q34,"") -> 53.333333 | S34: =IFERROR(R34/8,"") -> 6.6666667 | T34: =IFERROR(IF(R34>2,S34,""),"") -> 6.6666667 | U34: =1000/R34 -> 18.75 | V34: =R34*0.85 -> 45.333333 | AD34: 45378 | AE34: 14 / 15 | AF34: 0.8 | AG34: 0.1 | AH34: 1 | AI34: 0.13 | AJ34: 0.25 | AK34: 0.14 | AL34: 0.21 | AM34: 0.3 | AN34: 0.2 | AO34: 3.6 | AP34: 48 | AQ34: 103 | AR34: 103 | AS34: 103 | AT34: 40 | AU34: 20 | AV34: 40 | AW34: 20 | AX34: 100 | AY34: 294 | AZ34: Normal | BA34: 1200 | BB34: 10
A35: 1138 | B35: Venta Normal | C35: GN | D35: ART. 2060 (X 300) (DISCONTINUADO) | E35: 300 | F35: 0.025 | G35: 0.0204 | H35: =(F35-G35)/F35 -> 0.184 | I35: PET | J35: PET CRISTAL 460 x 250 | K35: CAJA Nº 1/2 | L35: BOLSAS DE 120 X 80 | O35: 2 | P35: 45 | Q35: =IFERROR(IF(AO35>1,AO35,60*60*8*O35/P35/E35),"") -> 4.2666667 | R35: =IFERROR(60*60*8*O35/E35/Q35,"") -> 45 | S35: =IFERROR(R35/8,"") -> 5.625 | T35: =IFERROR(IF(R35>2,S35,""),"") -> 5.625
A36: 1816 | B36: Venta Normal | C36: GN | D36: ART. 2060 MPH | E36: 520 | F36: 0.025 | G36: 0.0204 | H36: =(F36-G36)/F36 -> 0.184 | I36: PVC | J36: PVC CRISTAL 460 x 250 | K36: CAJA Nº 4/1 | L36: BOLSAS DE 120 X 125 | O36: 2 | P36: 28 | Q36: =IFERROR(IF(AO36>1,AO36,60*60*8*O36/P36/E36),"") -> 3.956044 | R36: =IFERROR(60*60*8*O36/E36/Q36,"") -> 28 | S36: =IFERROR(R36/8,"") -> 3.5 | T36: =IFERROR(IF(R36>2,S36,""),"") -> 3.5
A37: 2079 | B37: Venta Normal | C37: GN | D37: ART. 2060 MPH | E37: 200 | F37: 0.025 | G37: 0.0204 | H37: =(F37-G37)/F37 -> 0.184 | I37: PVC | J37: PVC CRISTAL 460 x 250 | K37: CAJA Nº 1/2 | L37: BOLSAS DE 120 X 80 | O37: 2 | P37: 73 | Q37: =IFERROR(IF(AO37>1,AO37,60*60*8*O37/P37/E37),"") -> 3.9452055 | R37: =IFERROR(60*60*8*O37/E37/Q37,"") -> 73 | S37: =IFERROR(R37/8,"") -> 9.125 | T37: =IFERROR(IF(R37>2,S37,""),"") -> 9.125
A38: 1817 | B38: Venta Normal | C38: GN | D38: ART. 2075 | E38: 200 | F38: 0.0403 | G38: 0.0348 | H38: =(F38-G38)/F38 -> 0.13647643 | I38: PVC | J38: PVC CRISTAL 480 x 250 | K38: CAJA Nº 4/1 | L38: BOLSAS DE 120 X 125 | O38: 2 | P38: 40 | Q38: =IFERROR(IF(AO38>1,AO38,60*60*8*O38/P38/E38),"") -> 7.2 | R38: =IFERROR(60*60*8*O38/E38/Q38,"") -> 40 | S38: =IFERROR(R38/8,"") -> 5 | T38: =IFERROR(IF(R38>2,S38,""),"") -> 5
A39: 1818 | B39: Venta Normal | C39: GN | D39: ART. 2095 | E39: 200 | F39: 0.0299 | G39: 0.0247 | H39: =(F39-G39)/F39 -> 0.17391304 | I39: PVC | J39: PVC CRISTAL 460 x 300 | K39: CAJA Nº 1/2 | L39: BOLSAS DE 120 X 80 | M39: 1 | N39: 200 | O39: 2 | P39: 58 | Q39: =IFERROR(IF(AO39>1,AO39,60*60*8*O39/P39/E39),"") -> 4.6 | R39: =IFERROR(60*60*8*O39/E39/Q39,"") -> 62.608696 | S39: =IFERROR(R39/8,"") -> 7.826087 | T39: =IFERROR(IF(R39>2,S39,""),"") -> 7.826087 | Z39: Christian | AD39: 45391 | AE39: 15 | AF39: 1 | AG39: 0.1 | AH39: 1 | AI39: 0.1 | AJ39: 0.5 | AK39: 0.2 | AL39: 0.16 | AM39: 0.7 | AN39: 0.3 | AO39: 4.6 | AP39: 45 | AQ39: 106 | AR39: 106 | AS39: 106 | AT39: 50 | AU39: 20 | AV39: 40 | AW39: 20 | AX39: 100 | AY39: 297 | AZ39: Normal | BA39: 1000 | BB39: 10
A40: 1819 | B40: Venta Normal | C40: GN | D40: ART. 2450 | E40: 360 | F40: 0.0343 | G40: 0.0283 | H40: =(F40-G40)/F40 -> 0.17492711 | I40: PVC | J40: PVC CRISTAL 560 x 250 | K40: CAJA Nº 17 | L40: BOLSAS DE 120 X 110 | M40: 2 | N40: 180 | O40: 2 | P40: 41 | Q40: =IFERROR(IF(AO40>1,AO40,60*60*8*O40/P40/E40),"") -> 3.6 | R40: =IFERROR(60*60*8*O40/E40/Q40,"") -> 44.444444 | S40: =IFERROR(R40/8,"") -> 5.5555556 | T40: =IFERROR(IF(R40>2,S40,""),"") -> 5.5555556 | Z40: Christian | AD40: 45504 | AE40: 12 | AF40: 0.8 | AG40: 0.15 | AH40: 0.8 | AI40: 0.15 | AJ40: 0.4 | AK40: 0.12 | AL40: 0.16 | AM40: 0.33 | AN40: 0.15 | AO40: 3.6 | AP40: 51 | AQ40: 104 | AR40: 104 | AS40: 104 | AT40: 40 | AU40: 30 | AV40: 40 | AW40: 40 | AX40: 100 | AY40: 330 | AZ40: Normal | BA40: 2400 | BB40: 10
...

Sheet Hoja3
A1: PRODUCT ID | B1: PRODUCT CODE | C1: Un per case | D1: Gross Weight (gr) | E1: Net Weight (gr) | F1: MATERIAL ( width (mm) thikness x (microns) ) | G1: CAV | H1: Cycle
A2: 692 | B2: POTE 1135 | C2: 500 | D2: 0.017 | E2: 0.01 | F2: PET CRISTAL 860 x 300 | G2: 24 | H2: 6
A3: 1924 | B3: POTE 1140 | C3: 500 | D3: 0.0193 | E3: 0.0111 | F3: PET CRISTAL 860 x 340 | G3: 24 | H3: 6
A4: 693 | B4: POTE 1145 | C4: 500 | D4: 0.0187 | E4: 0.0113 | F4: PET CRISTAL 860 x 330 | G4: 24 | H4: 6
A5: 1925 | B5: POTE 1150 | C5: 500 | D5: 0.0221 | E5: 0.013 | F5: PET CRISTAL 860 x 390 | G5: 24 | H5: 6
A6: 694 | B6: POTE 1165 | C6: 500 | D6: 0.0238 | E6: 0.0139 | F6: PET CRISTAL 860 x 420 | G6: 24 | H6: 6
A7: 1926 | B7: POTE 1170 | C7: 500 | D7: 0.0266 | E7: 0.0147 | F7: PET CRISTAL 860 x 470 | G7: 24 | H7: 6
A9: 1759 | B9: Z F 110 | C9: 720 | D9: 0.0167 | E9: 0.012 | F9: PET CRISTAL 820 x 350 | G9: 24 | H9: 6.6
A10: 1009 | B10: Z F 110 PERFORADA | C10: 720 | D10: 0.0184 | E10: 0.012 | F10: PET CRISTAL 820 x 350 | G10: 24 | H10: 6.6
A11: 1010 | B11: Z F 125 | C11: 720 | D11: 0.0167 | E11: 0.012 | F11: PET CRISTAL 820 x 350 | G11: 24 | H11: 6.6
A12: 1011 | B12: Z F 125 PERFORADA | C12: 720 | D12: 0.0184 | E12: 0.012 | F12: PET CRISTAL 820 x 350 | G12: 24 | H12: 6.6
A13: 1012 | B13: Z F 160 | C13: 720 | D13: 0.0167 | E13: 0.012 | F13: PET CRISTAL 820 x 350 | G13: 24 | H13: 6.6
A14: 1013 | B14: Z F 160 PERFORADA | C14: 720 | D14: 0.0184 | E14: 0.012 | F14: PET CRISTAL 820 x 350 | G14: 24 | H14: 6.6
... A22: 1844 | B22: ZDS TAPA | C22: 500 | D22: 0.0119 | E22: 0.007 | F22: PET CRISTAL 1020 x 400 | G22: 42 | H22: 16.6

Sheet Hoja4

Sheet Hoja2
A1: COD. | B1: ARTICULO | C1: UN por CAJA | D1: PESO BR. | E1: PESO NET. | F1: % SCRAP | G1: MATERIAL | H1: MATERIAL DETALLE | I1: CAJAS | J1: BOLSA | K1: CAV | L1: CAJAS POR TURNO | N1: Peso Promedio Real
A2: 692 | B2: POTE 1135 | C2: 500 | D2: 0.017 | E2: 0.01 | F2: 0.41176471 | G2: PET | H2: PET CRISTAL 860 x 300 | I2: CAJA Nº 11 | J2: BOLSAS DE 120 X 97 | K2: 24 | L2: 180
A3: 693 | B3: POTE 1145 | C3: 500 | D3: 0.0187 | E3: 0.0113 | F3: 0.39572193 | G3: PET | H3: PET CRISTAL 860 x 330 | I3: CAJA Nº 11 | J3: BOLSAS DE 120 X 97 | K3: 24 | L3: 180 | N3: 0.01112 | O3: =N3/E3-1 -> -0.015929204
A4: 694 | B4: POTE 1165 | C4: 500 | D4: 0.0238 | E4: 0.0139 | F4: 0.41596639 | G4: PET | H4: PET CRISTAL 860 x 420 | I4: CAJA Nº 11 | J4: BOLSAS DE 120 X 97 | K4: 24 | L4: 170 | N4: =13.975/1000 -> 0.013975 | O4: =N4/E4-1 -> 0.0053956835
A5: 867 | B5: POTE 1170 | C5: 800 | D5: 0.0266 | E5: 0.0147 | F5: 0.44736842 | G5: PET | H5: PET CRISTAL 860 x 470 | I5: CAJA Nº 13 | J5: BOLSAS DE 120 X 125 | K5: 24 | L5: 113
A6: 1844 | B6: ZDS TAPA | C6: 500 | D6: 0.0119 | E6: 0.007 | F6: 0.41176471 | G6: PET | H6: PET CRISTAL 1020 x 400 | I6: CAJA Nº 18 | J6: BOLSAS DE 25 X 50 | K6: 42 | L6: 110 | N6: 0.00688825 | O6: =N6/E6-1 -> -0.015964286
A7: 1845 | B7: ZDS 240 | C7: 500 | D7: 0.0145 | E7: 0.0085 | F7: 0.4137931 | G7: PET | H7: PET CRISTAL 915 x 450 | I7: CAJA Nº 21 | J7: BOLSAS DE 25 X 65 | K7: 36 | L7: 120
A8: 1846 | B8: ZDS 360 | C8: 500 | D8: 0.0177 | E8: 0.012 | F8: 0.3220339 | G8: PET | H8: PET CRISTAL 915 x 550 | I8: CAJA Nº 21 | J8: BOLSAS DE 25 X 65 | K8: 36 | L8: 117 | N8: =12.075/1000 -> 0.012075 | O8: =N8/E8-1 -> 0.00625
A9: 1847 | B9: ZDS 480 | C9: 500 | D9: 0.0193 | E9: 0.014 | F9: 0.2746114 | G9: PET | H9: PET CRISTAL 915 x 600 | I9: CAJA Nº 20 | J9: BOLSAS DE 25 X 70 | K9: 36 | L9: 116
A10: 1848 | B10: ZDS 720 | C10: 500 | D10: 0.0258 | E10: 0.021 | F10: 0.18604651 | G10: PET | H10: PET CRISTAL 915 x 800 | I10: CAJA Nº 19 | J10: BOLSAS DE 25 X 70 | K10: 36 | L10: 110
B16: Lámina de PET con Silicona en ambas caras
D17: Ancho (mm) | E17: Espesor (micrones)
A18: 867 | B18: POTE 1170 | C18: PET | D18: 860 | E18: 470 | F18: PET CRISTAL 860 x 470 | G18: 1 Rollo
D20: Ancho (mm) | E20: Espesor (micrones)
A21: 692 | B21: POTE 1135 | C21: PET | D21: 860 | E21: 300 | F21: PET CRISTAL 860 x 300 | G21: 10TN
A22: 1924 | B22: POTE 1140 | C22: PET | D22: 860 | E22: 340 | F22: PET CRISTAL 860 x 340 | G22: 10TN
A23: 693 | B23: POTE 1145 | C23: PET | D23: 860 | E23: 330 | F23: PET CRISTAL 860 x 330 | G23: 5TN
B24: Ajustar en proporción

Sheet BASE SEMI

Sheet GN Análisis
A1: COD. | B1: Estado | C1: Maquina | D1: ARTICULO | E1: UN por CAJA | F1: PESO BR. | G1: PESO NET. | H1: % SCRAP | I1: MATERIAL | J1: MATERIAL DETALLE | K1: CAJAS | L1: BOLSA | M1: CAV | N1: META | P1: Registrado por | Q1: FECHA | R1: MAQ | S1: Calentamiento | T1: Ventilador de calor | U1: Fomación | V1: Ventilador de forma | W1: intervalo de corte | X1: Retraso de expulsión | Y1: Expulsión | Z1: Transporte | AA1: Retraso de cierre | AB1: Promedio de ciclo | AC1: Molde | AD1: Zona1 | AE1: Zona2 | AF1: Zona3 | AG1: Precalentador | AH1: Presión de calentamiento | AI1: Presión de formación | AJ1: Presión de expusión | AK1: Velocidad | AL1: Recorrido | AM1: Modo | AN1: Acel/ Desacel | AO1: Velocidad del paso | AP1: Zona4 | AQ1: Zona5 | AZ1: Productos por minuto | BA1: Ciclo por minuto
A2: 1826 | B2: Venta Normal | C2: GN | D2: ART. 3110 PAI NEGRO | E2: 720 | F2: 0.0109 | G2: 0.0075 | H2: =(F2-G2)/F2 -> 0.31192661 | I2: HIPST | J2: PAI NEGRO 520 x 300 | K2: CAJA Nº 4/1 | L2: BOLSAS DE 120 X 125 | M2: 3 | N2: 25 | P2: Christian | Q2: 45420 | R2: 13 | S2: 1 | T2: 0.1 | U2: 1 | V2: 0.15 | W2: 0.45 | X2: 0.28 | Y2: 0.12 | Z2: 0.41 | AA2: 0.1 | AB2: 4 | AC2: 44 | AD2: 120 | AE2: 120 | AF2: 122 | AG2: 55 | AH2: 20 | AI2: 40 | AJ2: 20 | AK2: 65 | AL2: 178 | AM2: Normal | AN2: 500 | AO2: 10 | AY2: 7 | AZ2: =60*M2/AB2 -> 45 | BA2: =60/AB2 -> 15
A3: 1075 | B3: Venta Normal | C3: GN | D3: TAPA 50 OZ PAI NEGRO | E3: 240 | F3: 0.0129 | J3: PAI NEGRO 560 x 300 | M3: 6 | N3: 40 | R3: 12 | AB3: 9.2 | AZ3: =60*M3/AB3 -> 39.130435 | BA3: =60/AB3 -> 6.5217391
A4: 1946 | B4: Venta Normal | C4: GN | D4: Z T 2200 BASE NEGRO X 100 | E4: 100 | F4: 0.0307 | G4: 0.019 | H4: =(F4-G4)/F4 -> 0.38110749 | I4: PAI | J4: PAI NEGRO 550 x 350 | K4: CAJA Nº 8 | L4: BOLSAS DE 120 X 125 | M4: 2 | N4: 110 | P4: Christian | Q4: 44621 | R4: 12 | S4: 1.4 | T4: 0.4 | U4: 1.6 | V4: 0.4 | W4: 0.5 | X4: 0.28 | Y4: 0.14 | Z4: 0.3 | AA4: 0.2 | AB4: 5.6 | AC4: 50 | AD4: 128 | AE4: 128 | AF4: 129 | AG4: 75 | AH4: 30 | AI4: 40 | AJ4: 30 | AK4: 100 | AL4: 260 | AM4: Normal | AN4: 900 | AO4: 10 | AY4: 5 | AZ4: =60*M4/AB4 -> 21.428571 | BA4: =60/AB4 -> 10.714286
A5: 106 | B5: Venta Normal | C5: GN | D5: ART. BR 26 NEGRO | E5: 200 | F5: 0.0479 | G5: 0.032 | H5: =(F5-G5)/F5 -> 0.33194154 | I5: HIPST | J5: PAI NEGRO 340 x 400 | K5: CAJA Nº 9 | L5: BOLSAS DE 120 X 125 | M5: 1 | N5: 40 | P5: Christian | Q5: 45371 | R5: 12 | S5: 1.3 | T5: 0.4 | U5: 1.3 | V5: 0.4 | W5: 1 | X5: 0.12 | Y5: 0.22 | Z5: 0.55 | AA5: 0.2 | AB5: 5.8 | AC5: 51 | AD5: 138 | AE5: 135 | AF5: 135 | AG5: 60 | AH5: 33 | AI5: 40 | AJ5: 40 | AK5: 100 | AL5: 310 | AM5: Normal | AN5: 1600 | AO5: 10 | AY5: 4 | AZ5: =60*M5/AB5 -> 10.344828 | BA5: =60/AB5 -> 10.344828
A6: 108 | B6: Venta Normal | C6: GN | D6: ART. BR 29 NEGRO | E6: 100 | F6: 0.0594 | G6: 0.0444 | H6: =(F6-G6)/F6 -> 0.25252525 | I6: HIPST | J6: PAI NEGRO 365 x 400 | K6: CAJA Nº 5 | L6: BOLSAS DE 120 X 125 | M6: 1 | N6: 50 | P6: Christian | Q6: 45391 | R6: 12 | S6: 1.1 | T6: 0.5 | U6: 1.1 | V6: 0.3 | W6: 0.6 | X6: 0.11 | Y6: 0.17 | Z6: 0.2 | AA6: 0.12 | AB6: 4.6 | AC6: 45 | AD6: 132 | AE6: 136 | AF6: 135 | AG6: 60 | AH6: 38 | AI6: 40 | AJ6: 40 | AK6: 101 | AL6: 352 | AM6: Normal | AN6: 3000 | AO6: 10 | AY6: 6 | AZ6: =60*M6/AB6 -> 13.043478 | BA6: =60/AB6 -> 13.043478
A7: 99 | B7: Venta Normal | C7: GN | D7: ART. B 16 NEGRO X 160 | E7: 160 | F7: 0.0577 | G7: 0.046 | H7: =(F7-G7)/F7 -> 0.20277296 | I7: HIPST | J7: PAI NEGRO 320 x 400 | K7: CAJA Nº 4 | L7: BOLSAS DE 120 X 125 | M7: 1 | N7: 37 | P7: Christian | Q7: 45495 | R7: 13 | S7: 1.5 | T7: 0.5 | U7: 1.5 | V7: 0.5 | W7: 0.8 | X7: 0.11 | Y7: 0.18 | Z7: 0.4 | AA7: 0.5 | AB7: 6.3 | AC7: 56 | AD7: 119 | AE7: 128 | AF7: 128 | AG7: 65 | AH7: 20 | AI7: 40 | AJ7: 20 | AK7: 65 | AL7: 387 | AM7: Normal | AN7: 600 | AO7: 10 | AY7: 3 | AZ7: =60*M7/AB7 -> 9.5238095 | BA7: =60/AB7 -> 9.5238095
A8: 103 | B8: Venta Normal | C8: GN | D8: ART. BR 24 NEGRO | E8: 200 | F8: 0.0396 | G8: 0.0276 | H8: =(F8-G8)/F8 -> 0.3030303 | I8: HIPST | J8: PAI NEGRO 600 x 400 | K8: CAJA Nº 7 | L8: BOLSAS DE 120 X 125 | M8: 2 | N8: 60 | P8: Christian | Q8: 45497 | R8: 17 | S8: 1.9 | T8: 0.15 | U8: 1.8 | V8: 0.15 | W8: 1.2 | X8: 0.28 | Y8: 0.3 | Z8: 0.43 | AA8: 0.5 | AB8: 7.1 | AC8: 41 | AD8: 129 | AE8: 131 | AF8: 135 | AG8: 50 | AH8: ? | AI8: ? | AJ8: ? | AK8: 200 | AL8: 309 | AM8: Normal | AN8: ? | AO8: ? | AY8: 2 | AZ8: =60*M8/AB8 -> 16.901408 | BA8: =60/AB8 -> 8.4507042
A10: 8 | B10: Venta Normal | C10: GN | D10: BANDEJA 4 COMPARTIMENTOS | E10: 850 | F10: 0.0095 | G10: 0.0074 | H10: =(F10-G10)/F10 -> 0.22105263 | I10: PET | J10: PET CRISTAL 550 x 200 | K10: CAJA Nº 1 | L10: BOLSAS DE 120 X 97 | M10: 6 | N10: 25 | P10: Christian | Q10: 45421 | R10: 15 | S10: 1.4 | T10: 0.3 | U10: 1.4 | V10: 0.3 | W10: 0.5 | X10: 0.18 | Y10: 0.15 | Z10: 0.4 | AA10: 0.25 | AB10: 5.3 | AC10: 48 | AD10: 102 | AE10: 102 | AF10: 102 | AG10: 40 | AH10: 20 | AI10: 40 | AJ10: 20 | AK10: 100 | AL10: 338 | AM10: Normal | AN10: 1000 | AO10: 10 | AY10: 5 | AZ10: =60*M10/AB10 -> 67.924528 | BA10: =60/AB10 -> 11.320755
A11: 1135 | B11: Venta Normal | C11: GN | D11: PORCION CHICA | E11: 500 | F11: 0.0118 | G11: 0.0075 | H11: =(F11-G11)/F11 -> 0.36440678 | I11: PET | J11: PET CRISTAL 580 x 250 | K11: CAJA Nº 3 | L11: BOLSAS DE 120 X 97 | M11: 6 | N11: 40 | P11: Christian | Q11: 45499 | R11: 14 | S11: 2.3 | T11: 0.5 | U11: 2.3 | V11: 0.5 | W11: 1 | X11: 0.16 | Y11: 0.17 | Z11: 0.4 | AA11: 0.25 | AB11: 8.1 | AC11: 54 | AD11: 97 | AE11: 97 | AF11: 97 | AG11: 40 | AH11: 20 | AI11: 40 | AJ11: 20 | AK11: 70 | AL11: 315 | AM11: Normal | AN11: 900 | AO11: 10 | AY11: 2 | AZ11: =60*M11/AB11 -> 44.444444 | BA11: =60/AB11 -> 7.4074074
A12: 1915 | B12: Venta Normal | C12: GN | D12: ART. 2050 (X 300) | E12: 300 | F12: 0.025 | G12: 0.0204 | H12: =(F12-G12)/F12 -> 0.184 | I12: PET | J12: PET CRISTAL 460 x 250 | K12: CAJA Nº 1/2 | L12: BOLSAS DE 120 X 97 | M12: 2 | N12: 45 | P12: Christian | Q12: 45411 | R12: 16 | S12: 0.9 | T12: 0.1 | U12: 1 | V12: 0.1 | W12: 0.3 | X12: 0.36 | Y12: 0.2 | Z12: 0.14 | AA12: 0.5 | AB12: 4 | AC12: 45 | AD12: 104 | AE12: 109 | AF12: 114 | AG12: 40 | AL12: 383 | AP12: 111 | AQ12: 112 | AY12: 9 | AZ12: =60*M12/AB12 -> 30 | BA12: =60/AB12 -> 15
A13: 1916 | B13: Venta Normal | C13: GN | D13: ART. 2060 (X 300) | E13: 300 | F13: 0.025 | G13: 0.0204 | H13: =(F13-G13)/F13 -> 0.184 | I13: PET | J13: PET CRISTAL 460 x 250 | K13: CAJA Nº 1/2 | L13: BOLSAS DE 120 X 97 | M13: 2 | N13: 50 | P13: Christian | Q13: 45378 | R13: 15 | S13: 0.8 | T13: 0.1 | U13: 1 | V13: 0.13 | W13: 0.25 | X13: 0.14 | Y13: 0.21 | Z13: 0.3 | AA13: 0.2 | AB13: 3.6 | AC13: 48 | AD13: 103 | AE13: 103 | AF13: 103 | AG13: 40 | AH13: 20 | AI13: 40 | AJ13: 20 | AK13: 100 | AL13: 294 | AM13: Normal | AN13: 1200 | AO13: 10 | AY13: 10 | AZ13: =60*M13/AB13 -> 33.333333 | BA13: =60/AB13 -> 16.666667
A14: 1823 | B14: Venta Normal | C14: GN | D14: ART. 2510 | E14: 200 | F14: 0.0506 | G14: 0.0423 | H14: =(F14-G14)/F14 -> 0.16403162 | I14: PET | J14: PET CRISTAL 560 x 300 | K14: CAJA Nº 3 | L14: BOLSAS DE 120 X 97 | M14: 2 | N14: 55 | P14: Christian | Q14: 45419 | R14: 12 | S14: 0.9 | T14: 0.3 | U14: 1 | V14: 0.1 | W14: 0.14 | X14: 0.19 | Y14: 0.7 | Z14: 0.6 | AA14: 0.25 | AB14: 4.6 | AC14: 50 | AD14: 110 | AE14: 110 | AF14: 108 | AG14: 40 | AH14: 30 | AI14: 40 | AJ14: 40 | AK14: 100 | AL14: 406 | AM14: Normal | AN14: 1500 | AO14: 10 | AY14: 7 | AZ14: =60*M14/AB14 -> 26.086957 | BA14: =60/AB14 -> 13.043478
A15: 1136 | B15: Venta Normal | C15: GN | D15: PORCION GRANDE | E15: 500 | F15: 0.0142 | G15: 0.0088 | H15: =(F15-G15)/F15 -> 0.38028169 | I15: PET | J15: PET CRISTAL 580 x 300 | K15: CAJA Nº 3 | L15: BOLSAS DE 120 X 97 | M15: 6 | N15: 35 | P15: Christian | Q15: 45423 | R15: 14 | S15: 2 | T15: 0.5 | U15: 2 | V15: 0.5 | W15: 1.2 | X15: 0.15 | Y15: 0.17 | Z15: 0.6 | AA15: 0.3 | AB15: 8 | AC15: 55 | AD15: 99 | AE15: 99 | AF15: 99 | AG15: 40 | AH15: 20 | AI15: 40 | AJ15: 20 | AK15: 100 | AL15: 315 | AM15: Normal | AN15: 700 | AO15: 10 | AY15: 3 | AZ15: =60*M15/AB15 -> 45 | BA15: =60/AB15 -> 7.5
